Workbook

Sheet TS_calculation
B1: wB97XD/def2-tzvp SMD(MeOH) (T=298K)
B2: structure | C2: G(DFT) [Hartree] | D2: conc.[M] | E2: correction [Hartree] | F2: G(corrected) [Hartree] | G2: ΔG [Hartree] | H2: ΔG (vs BH4) [kcal/mol] | I2: ΔG (vs each phase) [kcal/mol] | J2: note
A3: 01_methanol autoionization
A4: MeOH | B4: 0 1 C 0.04753500 0.66335800 0.00000000 H 1.08808000 0.98858000 0.00000000 H -0.44449700 1.06730400 0.89048600 H -0.44449700 1.06730400 -0.89048600 O 0.04753500 -0.75593100 0.00000000 H -0.86457700 -1.05588800 0.00000000 | C4: -115.71429 | D4: 24.719 | E4: =0.593*LN(D4/0.0409)/627.5095 -> 0.0060520025 | F4: =E4+C4 -> -115.70824 | G4: 0 | H4: =627.5095*G4 -> 0 | I4: =H4 -> 0
A5: MeOH2+ | B5: 1 1 C 0.76675000 0.00000000 0.01778200 H 1.03626300 -0.00000700 1.06972200 H 1.09850200 -0.89724900 -0.49313200 H 1.09849900 0.89725700 -0.49311900 O -0.70204200 0.00000000 -0.09766900 H -1.10871400 -0.78969600 0.29559600 H -1.10871400 0.78969600 0.29559500 | C5: -116.12456 | F5: =E5+C5 -> -116.12456 | G5: =F5+F6-2*F4 -> 0.034316652 | H5: =627.5095*G5 -> 21.534025 | I5: =H5 -> 21.534025
A6: MeO- | B6: -1 1 C -0.00000200 -0.53025900 0.00000000 H 1.02400700 -1.03933700 0.00000000 H -0.51199000 -1.03934800 0.88681100 H -0.51199000 -1.03934800 -0.88681100 O -0.00000200 0.78744900 0.00000000 | C6: =-115.091076 -> -115.09108 | E6: =-104.5/627.5095 -> -0.16653134 | F6: =E6+C6 -> -115.25761 | G6: 0 | H6: =627.5095*G6 -> 0 | I6: =H6 -> 0 | J6: Calculated by applying the correction.
A7: 02_sodium methanolysis
A8: Na(MeOH)5+ | B8: 1 1 Na 0.01638800 0.24379400 -0.54910600 C 2.82187100 -1.44006600 0.03296100 O 2.11036400 -0.77542700 -1.00276500 H 2.12746700 -2.12291800 0.52123000 H 3.20441100 -0.73287500 0.77431300 H 3.65557700 -2.02010900 -0.37152800 H 2.71536800 -0.18688100 -1.46196000 C -1.22443300 -0.38342600 2.29478200 O 0.09162000 -0.21645700 1.78075300 H -1.74786100 0.56165700 2.15530700 H -1.20432100 -0.62077800 3.36138300 H -1.76401300 -1.17262400 1.76246100 H 0.59617600 -1.01312800 1.96594900 C 2.06904800 2.45418800 0.47065600 O 1.16834400 2.31627700 -0.62205500 H 2.67401700 1.54883600 0.50794000 H 1.53475100 2.56212500 1.41826800 H 2.73025600 3.31360400 0.33110100 H 0.61243400 3.09849200 -0.66184700 C -3.27882500 0.97369700 -0.51604200 O -1.96898100 1.51605300 -0.61736400 H -3.61789300 0.56845300 -1.47338800 H -3.99224600 1.72713500 -0.17187500 H -3.24303700 0.16897700 0.21738100 H -1.99065400 2.25972300 -1.22465800 C -0.55068600 -2.91331600 -0.41143800 O -1.18794800 -1.76665300 -0.96129900 H -0.37027100 -2.79295700 0.66125100 H 0.40387600 -3.03018600 -0.92243200 H -1.14926300 -3.81291200 -0.57471000 H -2.08408100 -1.72218500 -0.61769700 | C8: -740.7776 | D8: 0.05 | E8: =0.593*LN(D8/0.0409)/627.5095 -> 0.00018984496 | F8: =E8+C8 -> -740.77741 | G8: 0 | H8: =627.5095*G8 -> 0 | I8: =H8 -> 0
A9: Na+vac | B9: 1 1 Na 0.00000000 0.00000000 0.00000000 | C9: -162.09643 | F9: =E9+C9 -> -162.09643 | G9: =F9+5*F4-F8 -> 0.13977917 | H9: =627.5095*G9 -> 87.712755 | I9: =H9 -> 87.712755 | J9: good agreement in solvation energy (90.0 kcal/mol) : see https://doi.org/10.1039/D2CP03583A
A10: 03_NaBH4 reduction
A11: Na(BH4)(MeOH)4 | B11: 0 1 Na 0.13504500 -0.15703700 -0.13140600 C -2.66772300 1.55705600 -0.05390900 O -1.76289300 0.97183800 -0.98163500 H -2.08398200 2.18324900 0.61923800 H -3.18630700 0.79531600 0.53467800 H -3.40603000 2.18070700 -0.56524100 H -2.26304500 0.42964400 -1.59702600 C -2.36743500 -2.18297500 0.14738500 O -1.08408000 -2.20391600 -0.46538300 H -3.00525400 -1.53884700 -0.45666500 H -2.31708100 -1.78381900 1.16466100 H -2.80692100 -3.18346600 0.17693800 H -0.53480700 -2.84176000 -0.00107700 C 3.27773900 -1.11305700 -0.14163400 O 2.01656600 -1.46085000 -0.69734000 H 3.74574500 -0.29338000 -0.69385200 H 3.95555100 -1.97100000 -0.13293000 H 3.10178700 -0.79581600 0.88596700 H 2.14488400 -1.74376600 -1.60588200 C 0.79293600 2.97650200 0.05619300 O 1.46790200 1.82014300 -0.42489600 H 0.40883400 2.82061100 1.06864800 H -0.04173000 3.16797400 -0.61660900 H 1.45369300 3.84745600 0.05483600 H 2.24228700 1.67452000 0.12574100 B 0.19983400 -0.18486400 2.55935700 H 1.19467900 0.41442400 2.15946200 H 0.16112500 -0.17135200 3.78143400 H 0.24235400 -1.34288100 2.14885900 H -0.80351300 0.36102300 2.10331200 | C11: -652.41851 | D11: 0.05 | E11: =0.593*LN(D11/0.0409)/627.5095 -> 0.00018984496 | F11: =E11+C11 -> -652.41832 | G11: 0 | H11: =627.5095*G11 -> 0 | I11: =H11 -> 0
A12: Na(BH4)(eq-CyO)(MeOH)4 | B12: 0 1 O 1.36496900 0.28595700 -1.54768500 Na -1.59489400 -0.06955400 0.54836300 H -0.60201000 0.08918300 2.80526800 B 0.24163900 -0.69820100 2.37401700 H 0.77602700 -0.20602600 1.38627800 H -0.31566800 -1.74319100 2.04589800 H 1.08260800 -0.91713400 3.23424100 O -0.93514200 -1.26289300 -1.40405100 O -3.68122300 0.89796700 -0.28550700 C -1.70625300 -0.83795400 -2.51820100 C -3.91842700 2.19559100 0.24755000 H -3.76256900 2.13723100 1.32463800 H -3.22767800 2.92960600 -0.17449000 H -4.94593300 2.51750500 0.05882700 H -1.70297400 0.25222400 -2.61631700 H -1.33426800 -1.27659800 -3.44868500 H -2.73111600 -1.17513300 -2.36118800 H -0.03128300 -0.92476000 -1.52258600 H -3.76927100 0.93220400 -1.24132700 O -0.54491000 1.90975900 -0.31299200 C -0.05092600 2.81836300 0.65785600 H 0.65264700 2.33362200 1.34097900 H 0.44004700 3.67538400 0.18715800 H -0.90197000 3.18055200 1.23539400 H 0.20624100 1.53290800 -0.80034000 O -3.43329700 -1.45182700 1.27375200 H -4.03379500 -0.91353200 0.74342800 C -3.41779400 -2.77706400 0.76302500 H -4.38753300 -3.26500600 0.89699300 H -3.15282900 -2.79644200 -0.29814600 H -2.66515100 -3.33245000 1.32198800 C 2.44068200 0.08247200 -0.99968200 C 3.03811500 -1.28949400 -0.93859700 C 3.24121000 1.20602100 -0.41612300 C 3.67369600 -1.60050700 0.42024600 H 3.81819700 -1.30277000 -1.71046000 H 2.28099700 -2.02245300 -1.21781600 C 3.86745100 0.84922200 0.93518600 H 4.04225400 1.39975000 -1.14080000 H 2.61956000 2.09997300 -0.36216000 C 4.60491200 -0.48288100 0.87406800 H 4.21165500 -2.54723000 0.34877000 H 2.88152900 -1.73518300 1.16166400 H 4.54265900 1.65274400 1.23397200 H 3.07893300 0.79240500 1.69061500 H 5.01842600 -0.72237300 1.85597100 H 5.44874000 -0.40322700 0.18005100 | C12: -962.21783 | F12: -962.21783 | G12: =F12-F34-F11 -> 0.0040472541 | H12: =627.5095*G12 -> 2.5396904 | I12: =H12 -> 2.5396904
A13: [Na(BH4)(eq-CyO)(MeOH)4]‡ | B13: 0 1 O 1.19556800 -1.49535900 0.17527700 Na -1.92796500 -0.61279900 0.42788300 H -0.54376600 1.05001500 -0.94691600 B -0.02872200 1.56768700 0.00451100 H 1.20821900 0.56462400 -0.04552900 H -0.31870700 1.21247500 1.11305700 H 0.60889300 2.56714500 -0.14087700 O -0.52460800 -1.44681800 2.08445700 O -3.61135200 0.65549300 -0.54588200 C -0.72312600 -2.77877400 2.51826000 C -3.66709400 0.51851600 -1.96702400 H -2.64189400 0.55381900 -2.33276000 H -4.11796900 -0.43542300 -2.24803000 H -4.23409100 1.33796400 -2.41274200 H -0.91338200 -3.45506700 1.67677100 H 0.14577900 -3.15267800 3.07040900 H -1.58846900 -2.80361800 3.18290600 H 0.23596600 -1.44845700 1.41681300 H -4.50579600 0.66990900 -0.19441800 O -0.88265100 -1.73688900 -1.31194800 C -1.13130900 -3.09841900 -1.59559400 H -0.40301800 -3.49809000 -2.30979100 H -1.09862700 -3.71448600 -0.68969400 H -2.12635100 -3.18677600 -2.03581100 H 0.00037700 -1.66579800 -0.82161600 O -2.14630200 2.96768500 0.13383600 H -2.73964600 2.25460400 -0.15461600 C -2.41095900 3.23690900 1.49958200 H -3.39618400 3.69567500 1.63197800 H -2.35982300 2.32880800 2.10921200 H -1.65091500 3.93339000 1.85463200 C 1.90710300 -0.35851600 -0.03583000 C 2.89272100 -0.04042300 1.08597100 C 2.57511400 -0.30627900 -1.40784800 C 3.65972500 1.25650700 0.84531100 H 3.59242800 -0.88229800 1.14886000 H 2.34727200 -0.00171200 2.03301000 C 3.34142000 0.99236800 -1.63989000 H 3.26052600 -1.16018600 -1.46573300 H 1.81125000 -0.45189500 -2.17671200 C 4.34361600 1.25544600 -0.51921300 H 4.39567800 1.40614800 1.63926400 H 2.96431000 2.10123100 0.89731400 H 3.85178700 0.95576300 -2.60558300 H 2.63179600 1.82541000 -1.69004100 H 4.85243300 2.20847300 -0.68547400 H 5.11462900 0.47647400 -0.53540900 | C13: -962.17967 | F13: =E13+C13 -> -962.17967 | G13: =F13-F34-F11 -> 0.042205254 | H13: =627.5095*G13 -> 26.484198 | I13: =H13 -> 26.484198 | J13: NBO charge (H:-0.094, C:0.225)
A14: [Na(BH4)(ax-CyO)(MeOH)4]‡ | B14: 0 1 O 1.43670000 -0.72490000 0.16150000 Na -1.79590000 -0.78440000 0.58330000 H -1.12410000 0.92130000 -1.20940000 B -0.72930000 1.73550000 -0.42260000 H 0.73540000 1.11540000 -0.45900000 H -0.84400000 1.53870000 0.75510000 H -0.39820000 2.81860000 -0.80540000 O -0.12570000 -0.82900000 2.19080000 O -3.81860000 -0.27970000 -0.43920000 C 0.16090000 -1.99310000 2.94020000 C -3.87790000 -0.70890000 -1.80100000 H -2.92820000 -0.44300000 -2.26270000 H -4.01900000 -1.79000000 -1.86190000 H -4.68730000 -0.20300000 -2.33080000 H 0.20640000 -2.88410000 2.30340000 H 1.11430000 -1.90090000 3.47180000 H -0.63020000 -2.13740000 3.67830000 H 0.57100000 -0.74530000 1.45840000 H -4.66200000 -0.45930000 -0.01430000 O -0.52420000 -1.84780000 -1.05800000 C -0.38390000 -3.25230000 -0.97440000 H 0.43560000 -3.61130000 -1.60640000 H -0.19420000 -3.58070000 0.05420000 H -1.31030000 -3.71550000 -1.31880000 H 0.31100000 -1.42260000 -0.67570000 O -3.15350000 2.46510000 -0.31870000 H -3.48420000 1.55820000 -0.42770000 C -3.44960000 2.88170000 1.00300000 H -4.52750000 3.00350000 1.15050000 H -3.06920000 2.17270000 1.74550000 H -2.96390000 3.84430000 1.16490000 C 1.71240000 0.53320000 -0.27820000 C 2.40590000 0.55750000 -1.64220000 C 2.48420000 1.37520000 0.73900000 C 3.84820000 0.06750000 -1.52410000 H 2.39720000 1.58120000 -2.03140000 H 1.83750000 -0.06430000 -2.33900000 C 3.92660000 0.88710000 0.86230000 H 2.47780000 2.42190000 0.41680000 H 1.97140000 1.32540000 1.70310000 C 4.62620000 0.88540000 -0.49540000 H 4.33920000 0.11920000 -2.49920000 H 3.84860000 -0.98580000 -1.22550000 H 4.47290000 1.51680000 1.56920000 H 3.93130000 -0.12740000 1.27400000 H 5.64280000 0.49600000 -0.39510000 H 4.71610000 1.91800000 -0.85300000 | C14: -962.17563 | F14: =E14+C14 -> -962.17563 | G14: =F14-F34-F11 -> 0.046246254 | H14: =627.5095*G14 -> 29.019964 | I14: =H14 -> 29.019964
A15: [Na(BH4)(Ph2CO)(MeOH)4]‡ | B15: 0 1 O 0.56453500 -0.24878300 1.29965100 Na -2.70352300 0.02036700 0.81456500 H -1.49015000 -0.54719700 -1.33764000 B -0.89282700 0.48662800 -1.46423700 H 0.34612900 0.00555200 -0.74897300 H -1.13294800 1.39536100 -0.71897600 H -0.37168100 0.72474800 -2.51476000 O -1.30902600 1.38192700 2.07774200 O -4.42893800 -0.50269000 -0.62927000 C -1.34672700 1.31109800 3.49125500 C -4.39822900 -1.85198600 -1.09906500 H -3.35907700 -2.09083100 -1.32104900 H -4.77132500 -2.53758200 -0.33556500 H -4.99144100 -1.95792200 -2.00933500 H -1.33331200 0.27359400 3.84292300 H -0.49927400 1.83997800 3.93981400 H -2.26794400 1.78269100 3.83653500 H -0.51027000 0.86328100 1.76937200 H -5.33935000 -0.25055200 -0.45097700 O -1.44606000 -1.90489400 1.16531200 C -1.57169300 -2.67429900 2.34610700 H -0.76729100 -3.41263500 2.42744500 H -1.55758500 -2.04529800 3.24301500 H -2.52421300 -3.20525000 2.31030000 H -0.59746000 -1.37921900 1.21669100 O -3.42387600 1.31664600 -2.56835900 H -3.80109400 0.63860600 -1.98540700 C -3.68028600 2.58192700 -1.98592900 H -4.75476800 2.77573400 -1.90079000 H -3.22572000 2.67599300 -0.99354100 H -3.24113100 3.34112000 -2.63381100 C 1.14960500 -0.05715900 0.11419700 C 1.90753600 1.25595900 -0.03547100 C 2.46379600 1.61120700 -1.26210300 C 2.04957100 2.11623600 1.04292900 C 3.14767700 2.80621900 -1.40691300 H 2.35628100 0.94541100 -2.11150700 C 2.73851800 3.31542900 0.90154200 H 1.62141400 1.84583500 1.99954600 C 3.28749900 3.66453900 -0.32193200 H 3.57285600 3.07145200 -2.36755900 H 2.84391100 3.97765500 1.75277500 H 3.82252100 4.59992700 -0.43342700 C 1.96596100 -1.26710000 -0.33101500 C 1.44694700 -2.20864200 -1.20896300 C 3.22768400 -1.47709800 0.21924000 C 2.17620200 -3.34456100 -1.53766100 H 0.46374600 -2.05609600 -1.63942700 C 3.95625600 -2.61019600 -0.10545000 H 3.64264200 -0.74702100 0.90530900 C 3.43218200 -3.54794900 -0.98708100 H 1.76030500 -4.07010200 -2.22657400 H 4.93787400 -2.76169700 0.32759600 H 4.00316200 -4.43208500 -1.24377200 | C15: -1228.8716 | F15: =E15+C15 -> -1228.8716 | G15: =F15-F51-F11 -> 0.042290254 | H15: =627.5095*G15 -> 26.537536 | I15: =H15 -> 26.537536
A16: [Na(BH4)(PhMeCO)(MeOH)4]‡ | B16: 0 1 O -0.75351400 -1.52413700 0.52521200 Na 2.04254000 -0.43341500 -0.78157900 H 1.37753600 0.78313300 1.37906900 B 0.52676700 1.45467400 0.86377500 H -0.59422100 0.43877600 1.16003200 H 0.36294200 1.40168400 -0.32392000 H 0.04286700 2.36137300 1.47510200 O 0.07758200 -1.00875800 -1.86475900 O 4.02210300 0.69728500 -0.39399000 C -0.07176400 -2.16286600 -2.66831000 C 4.72294100 0.26279900 0.77305300 H 3.98229200 0.13004800 1.56049000 H 5.23046300 -0.68663100 0.59068300 H 5.45001900 1.01300200 1.08952800 H 0.26097200 -3.06561600 -2.14428100 H -1.11421900 -2.30461400 -2.97364100 H 0.53459100 -2.04247600 -3.56768000 H -0.35821100 -1.19030600 -0.97483400 H 4.65387800 0.86412200 -1.09882600 O 1.76105600 -1.96053800 0.96147600 C 2.04149300 -3.32342300 0.70598400 H 1.63143500 -3.96964900 1.48922000 H 1.63272500 -3.64707200 -0.25801300 H 3.12459700 -3.45503500 0.68392500 H 0.76628400 -1.82977800 0.91521300 O 2.54928200 3.04059500 0.19730300 H 3.14319500 2.28898000 0.03942800 C 2.21392200 3.60091800 -1.05983700 H 3.07903300 4.08387900 -1.52638500 H 1.81826000 2.84664700 -1.74799700 H 1.44230400 4.35336600 -0.89430700 C -1.30858900 -0.48438700 1.17021600 C -1.49690100 -0.73565000 2.66412700 H -2.21670100 -1.54682800 2.80154900 H -0.54328900 -1.03533000 3.10336900 H -1.86196800 0.14953400 3.18742500 C -2.56553000 0.07129200 0.51182500 C -3.08393300 1.30528400 0.89867900 C -3.21874100 -0.64611800 -0.48174200 C -4.23221100 1.80836700 0.30900800 H -2.57604100 1.88298500 1.66313300 C -4.37272900 -0.14607100 -1.07317800 H -2.81985000 -1.60274800 -0.79476800 C -4.88326100 1.08152800 -0.68067500 H -4.61909100 2.77207500 0.61856100 H -4.87138600 -0.71888700 -1.84630500 H -5.78045400 1.47395400 -1.14410700 | C16: -1037.1847 | F16: =E16+C16 -> -1037.1847 | G16: =F16-F53-F11 -> 0.043682254 | H16: =627.5095*G16 -> 27.411029 | I16: =H16 -> 27.411029
A17: [Na(BH4)(4-NO2PhMeCO)(MeOH)4]‡ | B17: 0 1 O 0.32369400 -1.69812600 0.71054800 Na 2.80220500 -0.25146100 -0.95982000 H 2.24458300 0.82220600 1.29509900 B 1.27966200 1.41975200 0.90434700 H 0.30331100 0.30878400 1.21960000 H 1.02291400 1.42550500 -0.26886700 H 0.78823400 2.25426200 1.60641300 O 0.79620700 -1.05579000 -1.75589600 O 4.71511600 0.99455500 -0.57068700 C 0.53242300 -2.11725800 -2.65129900 C 5.45956200 0.58149600 0.57714900 H 4.74458000 0.42400000 1.38313300 H 5.99259000 -0.35086000 0.38000100 H 6.17003900 1.35494000 0.87497400 H 0.91458900 -3.07046700 -2.27084200 H -0.54169000 -2.22359300 -2.83826000 H 1.02537400 -1.90202700 -3.60073200 H 0.49972100 -1.32981700 -0.83696500 H 5.32570200 1.19956700 -1.28413300 O 2.92114800 -1.87089000 0.74041000 C 3.23931200 -3.15726100 0.24001700 H 3.01045500 -3.93884100 0.97170700 H 2.69248900 -3.37812800 -0.68394300 H 4.30887700 -3.18816400 0.02638900 H 1.93031000 -1.83004000 0.86842900 O 3.17322100 3.28092200 0.09271000 H 3.77369500 2.53961800 -0.08649800 C 2.72398500 3.78337800 -1.15288400 H 3.54441600 4.22806100 -1.72618600 H 2.25280300 3.00303900 -1.76011400 H 1.98168200 4.55660600 -0.95248100 C -0.26560000 -0.70596300 1.38314400 C -0.22395500 -0.87687700 2.89856100 H -0.80998000 -1.75751400 3.17291500 H 0.80990700 -1.03178200 3.21170700 H -0.62492400 -0.00884600 3.42367400 C -1.65825100 -0.34462900 0.87996900 C -2.27836800 0.83596400 1.28495400 C -2.32522600 -1.19828800 0.01009900 C -3.54308700 1.16102200 0.83927500 H -1.76044200 1.51630200 1.94989300 C -3.59520000 -0.89267700 -0.44640400 H -1.84358700 -2.11116900 -0.31273400 C -4.18592200 0.28476100 -0.02270800 H -4.02243600 2.07782200 1.15023600 H -4.11528600 -1.55712600 -1.12123300 N -5.52343400 0.61710800 -0.50002800 O -6.03227600 1.65559800 -0.12258400 O -6.07892000 -0.15711800 -1.25624600 | C17: -1241.7109 | F17: =E17+C17 -> -1241.7109 | G17: =F17-F55-F11 -> 0.039779254 | H17: =627.5095*G17 -> 24.96186 | I17: =H17 -> 24.96186
A18: [Na(BH4)(4-MeOPhMeCO)(MeOH)4]‡ | B18: 0 1 O 0.06699000 -1.62952100 0.72123600 Na 2.58668600 -0.32930200 -0.97118700 H 2.12833500 0.80155700 1.28422800 B 1.20299300 1.45354600 0.88730700 H 0.15453900 0.36365500 1.25558100 H 0.90276300 1.42226300 -0.27426900 H 0.74199200 2.30854000 1.58445400 O 0.53489400 -1.03551700 -1.73939200 O 4.55559500 0.85810100 -0.66204200 C 0.19313000 -2.10052400 -2.60217100 C 5.31061400 0.43591400 0.47557300 H 4.60786400 0.30863300 1.29756900 H 5.81183100 -0.51395900 0.27862600 H 6.04959200 1.19099600 0.75020800 H 0.51373500 -3.06666300 -2.19749300 H -0.88752700 -2.14069100 -2.77864800 H 0.69016900 -1.94743100 -3.56178800 H 0.23989100 -1.27426100 -0.80395400 H 5.15692000 1.03266700 -1.39123300 O 2.63659100 -1.92257200 0.75652900 C 2.88929400 -3.22904700 0.27320700 H 2.60582000 -3.98974000 1.00810100 H 2.34438200 -3.42925400 -0.65692600 H 3.95836000 -3.32374000 0.07538000 H 1.64316800 -1.82795100 0.87517200 O 3.03581700 3.12441700 0.07661900 H 3.64966700 2.41402200 -0.17204700 C 2.55341700 3.72494200 -1.11229000 H 3.34654900 4.26899700 -1.63568200 H 2.12384100 2.98436400 -1.79489600 H 1.77066700 4.43136200 -0.83447700 C -0.47582400 -0.60283200 1.40365200 C -0.43904600 -0.80374500 2.91589900 H -1.06299800 -1.66223700 3.17827200 H 0.58651300 -1.00701600 3.23117600 H -0.80403200 0.07209900 3.45516100 C -1.84868400 -0.17472200 0.90407900 C -2.41746300 1.03208500 1.31351200 C -2.57076900 -0.97069300 0.03184800 C -3.66462900 1.42237200 0.87138200 H -1.86803500 1.68421500 1.98380700 C -3.83253600 -0.59708500 -0.42346400 H -2.14648400 -1.90776000 -0.30647700 C -4.38363100 0.60510600 -0.00188800 H -4.09848300 2.36301700 1.18900200 H -4.36449600 -1.24911700 -1.10225100 O -5.60156100 1.06806800 -0.38525500 C -6.37007700 0.27362000 -1.27152700 H -7.29378200 0.82260300 -1.44390500 H -5.85348400 0.12824700 -2.22430000 H -6.60516800 -0.69897400 -0.83030300 | C18: -1151.6885 | F18: =E18+C18 -> -1151.6885 | G18: =F18-F57-F11 -> 0.048747254 | H18: =627.5095*G18 -> 30.589365 | I18: =H18 -> 30.589365
A19: Na(BH3)(eq-CyHO)(MeOH)4 | B19: 0 1 O 1.55425400 -1.60534700 -0.27080700 Na -1.33997200 -0.65782200 0.56010500 H -0.80149600 1.44966200 -0.66586100 B -1.01056000 2.17826200 0.28443800 H 1.25406200 0.32178500 0.41351400 H -0.85129900 1.60773800 1.35608700 H -0.38500600 3.21209300 0.23164300 O 0.13793400 -1.92539200 1.80175700 O -3.53277400 0.13705900 0.00694800 C -0.06678500 -3.27770100 2.14934200 C -3.93052000 -0.21094700 -1.32495000 H -3.09064400 0.01825200 -1.97786600 H -4.16343400 -1.27462700 -1.38572000 H -4.79831800 0.37568800 -1.63032600 H -0.37627300 -3.87808300 1.28577800 H 0.84128800 -3.72568500 2.56884500 H -0.85376100 -3.33395600 2.90438700 H 0.79008900 -1.88058900 1.00828700 H -4.25747300 -0.04354100 0.61364000 O -0.67606400 -1.53606300 -1.49413400 C -1.11954600 -2.84179000 -1.79652700 H -0.47821000 -3.32073200 -2.54491100 H -1.14188800 -3.48273900 -0.90664200 H -2.13158000 -2.78513100 -2.20258900 H 0.26569700 -1.59321800 -1.09406100 O -2.53011400 2.55257000 0.17517000 H -3.05265000 1.70811500 0.09986700 C -3.06835400 3.37339400 1.22447200 H -4.12317000 3.54111600 1.01676600 H -2.93830700 2.88070600 2.18910000 H -2.52626900 4.31570100 1.20680900 C 2.01193600 -0.29247900 -0.11623900 C 3.27880900 -0.23741800 0.73805100 C 2.25540500 0.39229100 -1.46141700 C 3.79244800 1.18907900 0.91644800 H 4.04611700 -0.85014600 0.24855200 H 3.07281100 -0.69569800 1.71022800 C 2.76540200 1.82153400 -1.29429800 H 2.99007000 -0.20260800 -2.01841500 H 1.32849000 0.38487800 -2.04241400 C 4.02327400 1.86767800 -0.43108700 H 4.71428600 1.18837600 1.50425800 H 3.05655700 1.76779300 1.48693900 H 2.95965700 2.26918200 -2.27265300 H 1.98357800 2.42733500 -0.82152900 H 4.34284100 2.90284700 -0.28351300 H 4.83842800 1.35577400 -0.95578100 | C19: -962.20467 | F19: =E19+C19 -> -962.20467 | G19: =F19-F34-F11 -> 0.017205254 | H19: =627.5095*G19 -> 10.79646 | I19: =H19 -> 10.79646
A20: MeOH・BH3 (via CyO reduction) | F20: =F30 -> -142.33408 | G20: =F20+F8+F60-3*F4-(F11-G11)-F34+F6 -> -0.013663252 | H20: =627.5095*G20 -> -8.5738203 | I20: =H20 -> -8.5738203
A21: MeOBH3- (via CyO reduction) | F21: =F31 -> -141.88832 | G21: =F21+F8+F60-3*F4-(F11-G11)-F34+F4 -> -0.018536906 | H21: =627.5095*G21 -> -11.632085 | I21: =H21 -> -11.632085
A22: Na(MeOBH3)(MeOH)4 (via CyO reduction) | F22: =F32 -> -766.96319 | G22: =F22+F60-F4-(F11-G11)-F34 -> -0.024236748 | H22: =627.5095*G22 -> -15.20879 | I22: =H22 -> -15.20879
A23: 04_BH4- methanolysis
A24: BH4- | B24: -1 1 B 0.00000000 0.00000000 0.00000000 H 0.70973300 0.70973300 0.70973300 H -0.70973300 -0.70973300 0.70973300 H -0.70973300 0.70973300 -0.70973300 H 0.70973300 -0.70973300 -0.70973300 | C24: -27.346349 | F24: =E24+C24 -> -27.346349 | G24: =F24+F8-F11-F4 -> 0.0027979975 | H24: =627.5095*G24 -> 1.75577 | I24: =H24 -> 1.75577
A25: MeOH2・BH4 | B25: 0 1 B 2.11262100 0.18049600 0.02870900 H 1.65758800 1.26759400 -0.29477200 H 3.30639800 0.11373900 -0.21114100 H 0.31134500 -0.61145400 -0.25269900 H 1.59315700 -0.70615000 -0.67128300 O -0.70289700 -0.71325800 -0.10159200 C -1.37762400 0.57768300 0.01821000 H -1.16232200 1.11199000 -0.90130200 H -2.43809300 0.36453500 0.10931600 H -0.99455400 1.10584600 0.88742500 H -0.83641800 -1.26542600 0.68478400 H 1.88871800 -0.04319000 1.20960500 | C25: -143.47369 | F25: =E25+C25 -> -143.47369 | G25: =F25+F8+F6-3*F4-F11 -> 0.034327649 | H25: =627.5095*G25 -> 21.540926 | I25: =H25 -> 21.540926
A26: [MeOH2・BH4]‡ | B26: 0 1 B 2.22946500 -0.13163800 0.00052200 H 2.11772500 0.97707500 -0.47500300 H 2.99790300 -0.82446100 -0.62933500 H 0.58375700 -0.07580200 -0.04990800 H 1.18486000 -0.84455200 -0.18586500 O -0.53581700 0.53677500 0.11983800 H 2.44105700 -0.12123000 1.19287400 C -1.64307900 -0.36886600 -0.02457100 H -1.50957800 -1.14460700 0.72580600 H -2.56949300 0.17160300 0.16108200 H -1.65084700 -0.80780500 -1.02239800 H -0.59770200 1.24696300 -0.53114200 | C26: -143.4733 | F26: =E26+C26 -> -143.4733 | G26: =F26-(F25-G25) -> 0.034719649 | H26: =627.5095*G26 -> 21.78691 | I26: =H26 -> 21.78691
A27: BH3-σ(H2) | B27: 0 1 B 0.19033900 0.00579400 -0.00001600 H 0.25573300 1.20864400 -0.00139700 H 0.51956100 -0.51243200 -1.03023300 H 0.51997100 -0.51019500 1.03118600 H -1.15373100 0.29935000 0.00016100 H -1.09323000 -0.51433900 0.00036100 | C27: -27.777504 | F27: =E27+C27 -> -27.777504 | G27: =F27+F4-(F26-G26) -> 0.022276652 | H27: =627.5095*G27 -> 13.978811 | I27: =H27 -> 13.978811
A28: [MeOH・BH3・H2]‡ | B28: 0 1 B -1.71778600 -0.01979900 -0.00818700 H -1.46874500 -0.76425200 -0.91010100 H -1.48385100 -0.34412600 1.11777700 H -2.01375100 1.11372200 -0.25213100 H -3.31157200 -0.88578200 0.01486000 H -3.51721600 -0.16002600 0.11824900 O 0.71814100 0.68408600 -0.12767300 H 0.78904200 1.19558800 0.68245100 C 1.47362500 -0.50780200 0.02464400 H 1.37444400 -1.07505400 -0.90055600 H 2.53250800 -0.28877800 0.19100500 H 1.10119200 -1.11817500 0.85290500 | C28: -143.47596 | F28: =E28+C28 -> -143.47596 | G28: =F28-F4-(F27-G27) -> 0.032057649 | H28: =627.5095*G28 -> 20.116479 | I28: =H28 -> 20.116479
A29: H2 | B29: 0 1 H 0.00000000 0.00000000 0.37254100 H 0.00000000 0.00000000 -0.37254100 | C29: -1.177343 | F29: =E29+C29 -> -1.177343 | G29: 0 | H29: =627.5095*G29 -> 0 | I29: =H29 -> 0
A30: MeOH・BH3 | B30: 0 1 B -1.37078000 -0.26360800 0.02374300 H -1.37063800 -1.06185900 -0.88903900 H -1.36740200 -0.80124800 1.11538700 H -2.22367700 0.59061100 -0.08403200 O 0.00367600 0.51900400 -0.12270400 H 0.03665400 1.29472500 0.45031300 C 1.21065000 -0.25548300 0.02259400 H 2.05897800 0.40770700 -0.13066500 H 1.24369800 -0.70939600 1.01305700 H 1.18297800 -1.02163700 -0.74766900 | C30: -142.33408 | F30: =E30+C30 -> -142.33408 | G30: =F30+F29-(F28-G28) -> -0.0034003508 | H30: =627.5095*G30 -> -2.1337524 | I30: =H30 -> -2.1337524
A31: (MeO)BH3- | B31: -1 1 B 1.26973800 0.20119300 0.00004300 H 1.34506700 0.93326700 -1.00517500 H 1.34500900 0.93295500 1.00549200 H 2.21936600 -0.58409100 -0.00005500 O 0.01147500 -0.58393300 -0.00011200 C -1.15022000 0.19293000 0.00003400 H -2.02889200 -0.46026000 -0.00013700 H -1.20988400 0.84282300 0.88708400 H -1.20983900 0.84322300 -0.88672900 | C31: -141.88832 | F31: =E31+C31 -> -141.88832 | G31: =F31+F4-F6-(F30-G30) -> -0.008274005 | H31: =627.5095*G31 -> -5.1920167 | I31: =H31 -> -5.1920167
A32: Na(MeOBH3)(MeOH)4 | B32: 0 1 Na 0.02717800 0.11601800 -0.07381900 C 2.66401700 -1.84248500 0.50251000 O 1.93025600 -1.12552400 -0.44638100 H 1.98634500 -2.45381400 1.10565600 H 3.21606300 -1.17363400 1.17924000 H 3.39655300 -2.51171400 0.02832400 C -2.35785000 -0.37059000 1.92138500 O -0.96029200 -0.62808100 1.96449500 H -2.48468300 0.70247700 1.78076100 H -2.84357600 -0.66206000 2.85638900 H -2.83650300 -0.89751600 1.09073700 H -0.82492100 -1.56828000 2.11013900 C 1.50076300 3.02616600 0.44508300 O 1.57918700 1.69469500 0.93125800 H 0.59104600 3.47100600 0.84723200 H 1.45584100 3.05124300 -0.64828500 H 2.35780800 3.62055300 0.77536800 H 2.35073100 1.27634900 0.52115900 C -2.63923100 1.62316400 -1.35139800 O -1.37738500 1.88551800 -0.75238600 H -2.52635100 1.24461900 -2.37095200 H -3.26131200 2.52195700 -1.36938100 H -3.13725000 0.86765100 -0.74442600 H -0.94068300 2.58284400 -1.24817400 C -1.20842200 -2.79185200 -0.64753900 O -1.33785200 -1.48906600 -1.19973100 H -1.72445400 -2.87360000 0.31379400 H -0.14499200 -2.97482500 -0.49719600 H -1.60312200 -3.55090500 -1.32850900 H -2.27134300 -1.29522700 -1.31576800 H 3.47421500 -0.90682700 -2.08011100 H 1.94004800 0.41507500 -2.01316700 H 3.44996600 0.52294600 -0.67570300 B 2.73092600 -0.25025500 -1.34067900 | C32: -766.96319 | F32: =E32+C32 -> -766.96319 | G32: =F32+F4-F8-(F31-G31) -> -0.013973847 | H32: =627.5095*G32 -> -8.768722 | I32: =H32 -> -8.768722
A33: 05_BH3 reduction
A34: CyO | B34: 0 1 C -1.01091100 -1.25584800 -0.28186700 C 0.39195700 -1.27506400 0.33632500 C 0.39195400 1.27505900 0.33634200 C -1.01091400 1.25585100 -0.28184500 C -1.77878000 -0.00000300 0.11308800 H 0.30024300 -1.35415200 1.42617600 H 0.98228700 -2.12139500 -0.01514700 H -0.92161600 -1.29822100 -1.37187300 H -1.54990400 -2.15260400 0.02889500 H 0.30024600 1.35413200 1.42619400 H 0.98228300 2.12139600 -0.01511700 H -1.54990800 2.15260100 0.02893400 H -0.92162300 1.29824500 -1.37185100 H -1.94661500 -0.00001200 1.19554700 H -2.76159700 0.00000100 -0.36337100 C 1.14219000 0.00000000 0.06530000 O 2.29165400 0.00000400 -0.33655600 | C34: -309.80506 | D34: 0.2 | E34: =0.593*LN(D34/0.0409)/627.5095 -> 0.0014999009 | F34: =E34+C34 -> -309.80356 | G34: 0 | H34: =627.5095*G34 -> 0 | I34: =H34 -> 0
A35: [CyO・BH3・MeOH]‡ | B35: 0 1 B 2.17283000 -0.40378200 -0.30148900 H 1.99168700 -0.09124000 -1.44284600 H 1.98258600 0.39043400 0.57441500 H 2.58047800 -1.49662800 -0.03554000 O 0.11732400 -1.20944900 -0.11335500 C -0.94084700 -0.62578800 -0.29172900 C -1.01509000 0.82200200 -0.67596500 C -2.25115100 -1.34523800 -0.15510800 C -2.04211000 1.58406900 0.17061500 H -1.33250900 0.84025300 -1.72544200 H -0.02622000 1.27216200 -0.61575500 C -3.25689900 -0.55091400 0.68591900 H -2.64521600 -1.45607300 -1.17241600 H -2.07447200 -2.34166000 0.24936400 C -3.39389600 0.88144700 0.18487900 H -2.13707600 2.59878200 -0.21958200 H -1.66612000 1.66896700 1.19479700 H -4.22006000 -1.06355100 0.66429300 H -2.92242700 -0.54112400 1.72781400 H -4.09211500 1.43226900 0.81880000 H -3.81336200 0.87583900 -0.82688700 O 4.31092900 0.30147000 -0.46222800 H 4.25398700 1.23569000 -0.68245100 C 4.96853200 0.16899200 0.79067200 H 5.01970100 -0.89531100 1.01726500 H 4.41595200 0.67519500 1.58721800 H 5.98377500 0.57132200 0.74337800 | C35: -452.10698 | F35: =E35+C35 -> -452.10698 | G35: =F35-F34-(F30-G30) -> 0.027254748 | H35: =627.5095*G35 -> 17.102613 | I35: =H35-H$32 -> 25.871335
A36: CyO・BH3 | B36: 0 1 C 1.17186100 1.41221000 -0.25316400 C -0.20523900 1.10292400 0.34545600 C 0.38888500 -1.38570000 0.27007500 C 1.74171800 -1.02349600 -0.34777200 C 2.20559700 0.35403700 0.10527300 H -0.16374100 1.21319500 1.43813400 H -0.97008000 1.78483100 -0.01844400 H 1.07609100 1.47264300 -1.34079500 H 1.48385100 2.39708900 0.09600100 H 0.51382600 -1.51302900 1.35399800 H -0.02077100 -2.31461900 -0.12443900 H 2.46595600 -1.79078800 -0.07198000 H 1.65355800 -1.03986200 -1.43769400 H 2.36956300 0.34934500 1.18785700 H 3.16051500 0.59760700 -0.36437400 C -0.62289900 -0.30536600 0.13515800 O -1.79680200 -0.63859000 -0.09155200 B -3.05376500 0.30461500 -0.18144900 H -2.88815800 1.05117000 -1.12613300 H -3.13525100 0.90874800 0.86992300 H -3.98164600 -0.45834600 -0.35254300 | C36: -336.42335 | F36: =E36+C36 -> -336.42335 | G36: =F36+F4-(F35-G35) -> 0.0026507508 | H36: =627.5095*G36 -> 1.6633713 | I36: =H36-H$32 -> 10.432093
A37: [eq-CyO・BH3]‡ | B37: 0 1 B 2.34672700 -0.00001400 1.01063400 H 1.27226000 -0.00003200 1.60066600 O 1.99122200 0.00000400 -0.60622600 H 2.94098300 -1.03221800 1.20082300 H 2.94096600 1.03219400 1.20085300 C 0.73368900 0.00000500 -0.45342200 C -0.02128800 1.27908000 -0.47391000 C -0.02129500 -1.27906500 -0.47395800 C -1.30353400 1.25502700 0.35728100 H -0.27427500 1.39964200 -1.53784100 H 0.64580800 2.09882400 -0.20940900 C -1.30354000 -1.25503700 0.35723400 H -0.27428200 -1.39958800 -1.53789300 H 0.64579800 -2.09882300 -0.20948600 C -2.12443300 0.00000200 0.08943800 H -1.88247700 2.15230500 0.13518600 H -1.03571600 1.29748000 1.41668700 H -1.88248800 -2.15230300 0.13510800 H -1.03572200 -1.29753000 1.41663900 H -2.46639600 0.00002200 -0.95077600 H -3.01546800 -0.00000700 0.72010200 | C37: -336.39984 | F37: =E37+C37 -> -336.39984 | G37: =F37-(F36-G36) -> 0.026160751 | H37: =627.5095*G37 -> 16.41612 | I37: =H37-H$32 -> 25.184842
A38: [ax-CyO・BH3]‡ | B38: 0 1 B 2.79731000 0.00001700 0.24251300 H 2.23757000 0.00005400 1.33656800 O 1.59510200 -0.00005600 -0.87532200 H 3.39507400 -1.03452000 0.08074800 H 3.39503800 1.03456100 0.08065800 C 0.68996600 -0.00000400 0.01808200 C 0.02056600 -1.26464300 0.42198200 C 0.02057700 1.26468400 0.42184500 C -1.37235100 -1.25826300 -0.25037900 H -0.11017600 -1.27394700 1.50527800 H 0.61151300 -2.12403400 0.11085000 C -1.37234200 1.25824300 -0.25051100 H -0.11016300 1.27410600 1.50514100 H 0.61152900 2.12403700 0.11062100 C -2.15287200 0.00001100 0.11002400 H -1.90426400 -2.15600900 0.06601900 H -1.24512500 -1.32012800 -1.33478400 H -1.90424900 2.15602400 0.06579500 H -1.24511800 1.31999500 -1.33492300 H -2.36808100 0.00006800 1.18314000 H -3.11218700 -0.00001200 -0.41135500 | C38: -336.39553 | F38: =E38+C38 -> -336.39553 | G38: =F38-(F36-G36) -> 0.030462751 | H38: =627.5095*G38 -> 19.115665 | I38: =H38-H$32 -> 27.884388
A39: eq-CyOH・BH2 | B39: 0 1 C 1.48598900 -1.25883000 0.26561100 C 0.05289500 -1.25735800 -0.26171700 C 0.05284300 1.25732300 -0.26177600 C 1.48593800 1.25887600 0.26555100 C 2.23643400 0.00002700 -0.15973400 H 0.06032300 -1.29446700 -1.35639100 H -0.49103900 -2.13610400 0.09348700 H 1.46811100 -1.31576800 1.35957300 H 2.00620300 -2.15167900 -0.08803300 H 0.06027100 1.29438000 -1.35645200 H -0.49112400 2.13606300 0.09337800 H 2.00611300 2.15172800 -0.08814500 H 1.46805800 1.31586800 1.35951400 H 2.35168600 0.00000600 -1.24937100 H 3.24256100 0.00006100 0.26647100 C -0.67999600 -0.00002300 0.17195200 O -1.99222700 -0.00006800 -0.41269000 B -3.11027500 0.00003900 0.32577300 H -3.05469400 0.00017300 1.52556200 H -4.15111300 -0.00000800 -0.26824700 H -0.79078400 0.00000100 1.26199400 | C39: -336.45968 | F39: =E39+C39 -> -336.45968 | G39: =F39-(F36-G36) -> -0.033681249 | H39: =627.5095*G39 -> -21.135304 | I39: =H39-H$32 -> -12.366582
A40: MeOBH2 | B40: 0 1 O -0.14776300 -0.49545100 0.00002800 B -1.28058800 0.22485800 0.00001000 H -1.24337200 1.42522200 -0.00005800 H -2.30902000 -0.38909600 0.00005100 C 1.12759000 0.14933600 -0.00002400 H 1.24060600 0.76740700 0.89173700 H 1.89073300 -0.62759600 -0.00002900 H 1.24055700 0.76736600 -0.89182500 | C40: -141.18083 | F40: =E40+C40 -> -141.18083 | G40: =F40+F60-(F39-G39)-F4 -> -0.037758252 | H40: =627.5095*G40 -> -23.693662 | I40: =H40-H$32 -> -14.92494
...

Sheet summery
C1: CyO | E1: acetophenone
B2: methanolysis | C2: eq | D2: ax | E2: 4‘-NO2 | F2: H | G2: 4‘-MeO
A3: NaBH4 | B3: =TS_calculation!I26 -> 21.78691 | C3: =TS_calculation!I13 -> 26.484198 | D3: =TS_calculation!I14 -> 29.019964 | E3: =TS_calculation!I17 -> 24.96186 | F3: =TS_calculation!I15 -> 26.537536 | G3: =TS_calculation!I18 -> 30.589365
A4: Na(MeO)BH3 | B4: =TS_calculation!I43 -> 22.980335 | C4: =TS_calculation!I49 -> 13.802135 | D4: =TS_calculation!I50 -> 15.861621 | E4: =TS_calculation!I56 -> 14.180523 | F4: =TS_calculation!I54 -> 15.414207 | G4: =TS_calculation!I58 -> 18.441313
A5: Na(MeO)2BH2 | B5: =TS_calculation!I74 -> 26.347551 | C5: =TS_calculation!I80 -> 15.357731 | D5: =TS_calculation!I81 -> 17.343171 | E5: =TS_calculation!I84 -> 13.985995 | F5: =TS_calculation!I83 -> 16.220557 | G5: =TS_calculation!I85 -> 17.564682
A6: Na(MeO)3BH | B6: =TS_calculation!I100 -> 28.38884 | C6: =TS_calculation!I106 -> 16.170984 | D6: =TS_calculation!I107 -> 18.664079 | E6: =TS_calculation!I110 -> 15.567319 | F6: =TS_calculation!I109 -> 19.041212 | G6: =TS_calculation!I111 -> 20.117391
A7: average | B7: =AVERAGE(B4:B6) -> 25.905576 | C7: =AVERAGE(C4:C6) -> 15.110283 | D7: =AVERAGE(D4:D6) -> 17.289624 | E7: =AVERAGE(E4:E6) -> 14.577946 | F7: =AVERAGE(F4:F6) -> 16.891992 | G7: =AVERAGE(G4:G6) -> 18.707795
A8: Experiment | B8: - | C8: =-2.56 -> -2.56 | D8: =-1.72 -> -1.72 | E8: -2.02 | F8: -0.25 | G8: 0.56

Sheet EDA
B2: Bond Energy | C2: Orbital Energy | D2: Electrostatic Energy | E2: Pauli Energy | F2: Delta E^0(XC) | G2: Delta Dispersion | H2: total
A3: benzophenone | B3: -33.16 | C3: -70.93 | D3: -76.51 | E3: 183.42 | F3: -58.52 | G3: -10.62 | H3: =SUM(B3:G3) -> -66.32
A4: Cyclohexanone (eq) | B4: -39.12 | C4: -77.64 | D4: -85.44 | E4: 200.49 | F4: -65.61 | G4: -10.91 | H4: =SUM(B4:G4) -> -78.23
A5: Cyclohexanone (ax) | B5: -34.92 | C5: -76.99 | D5: -79.88 | E5: 193.44 | F5: -61.8 | G5: -9.7 | H5: =SUM(B5:G5) -> -69.85
