Workbook

Sheet dataset
D1: unit: kcal/mol | F1: Competitive reaction: 0 (training data), regioselective data: 1 (test data) | G1: Distinguish symmetry and reaction face | I1: A1 = fluorenone | L1: A2 = benzophenone | N1: substrate1=dibenzosuberone | T1: for acetophenone skelton (from ref https://pubs.acs.org/doi/pdf/10.1021/cr00002a004?casa_token=xCt8l1UZ8wMAAAAA:RPkuIj9tMEk-r-GBzRkKO6zfp1iCt2HTOClZQQm07YvdOjqoodlWRBhZ8BGXCjV2KWi9O3-I1KyW7kkO9qo) | U1: for diaryl cycloketone | V1: 1H-NMR reference
A2: entry | B2: Supplier (Catalog No.) | C2: CAS RN | D2: name | E2: analogue | F2: test | G2: SMILES | H2: temperature | I2: ΔΔG | J2: benzophenone correction | K2: ±σ | L2: ΔΔG | M2: ±σ | N2: ΔΔG | O2: benzophenone correction | P2: ±σ | Q2: ΔΔG.expt. | R2: ±σ.expt. | S2: k2/k1 | T2: Hammett σ | U2: carbonyl angle | V2: ketone | W2: alcohol | X2: reference | Y2: isolated yield after reduction to monoketone
A3: C12 | B3: TCI(C1335) | C3: 13547-70-1 | D3: ='A1 = fluorenone'!A3 -> 1-chloropinacolin | E3: chain | F3: 0 | G3: O=C(CCl)C(C)(C)C | H3: 273 | I3: ='A1 = fluorenone'!Q3 -> -0.85181055 | J3: =I3+$L$22 -> -2.6011303 | K3: ='A1 = fluorenone'!R3 -> 0.013977079 | L3: ='A1 = benzophenone'!Q34 -> -2.1120317 | M3: ='A1 = benzophenone'!$R$34 -> 0.12903075 | Q3: =J3 -> -2.6011303 | R3: =K3 -> 0.013977079 | S3: =EXP(-Q3/1.99/H3*1000) -> 120.05074 | V3: SDBS(No.:19329) | W3: Degennaro, Leonardo, et al. "External trapping of halomethyllithium enabled by flow microreactors." Advanced Synthesis & Catalysis 357.1 (2015): 21-27. | X3: this work
A4: A12 | B4: TCI(T0848) | C4: 434-45-7 | D4: ='A1 = fluorenone'!A8 -> 2,2,2-trifluoroacetophenone | E4: acetophenone | F4: 0 | G4: O=C(C(F)(F)F)c1ccccc1 | H4: 273 | I4: ='A1 = fluorenone'!Q8 -> -0.57734173 | J4: =I4+$L$22 -> -2.3266615 | K4: ='A1 = fluorenone'!R8 -> 0.062382414 | Q4: =J4 -> -2.3266615 | R4: =K4 -> 0.062382414 | S4: =EXP(-Q4/1.99/H4*1000) -> 72.435626 | V4: SDBS(No.:10872) | W4: Peng, Peng, et al. "Lithium triethylborohydride-promoted generation of α, α-difluoroenolates from 2-iodo-2, 2-difluoroacetophenones: an unprecedented utilization of lithium triethylborohydride." RSC Advances 7.88 (2017): 56034-56037. | X4: this work
A5: D100 | B5: TCI(C1292) | C5: 4746-97-8 | D5: ='A1 = fluorenone'!A13 -> 1,4-Cyclohexanedion monoethyleneketal | F5: 0 | G5: O=C1[13CH2]CC2(OCCO2)CC1 | H5: 273 | I5: ='A1 = fluorenone'!Q13 -> -0.51730459 | J5: =I5+$L$22 -> -2.2666243 | K5: ='A1 = fluorenone'!R13 -> 0.0090008289 | Q5: =J5 -> -2.2666243 | R5: =K5 -> 0.0090008289 | S5: =EXP(-Q5/1.99/H5*1000) -> 64.857176 | V5: Scifinder(Spectrum ID EN300-26857, Spectral data were obtained from Enamine Ltd.) | W5: Scifinder(Spectrum ID EN300-39891, Spectral data were obtained from Enamine Ltd.) | X5: this work
A6: D99(trans) | B6: TCI(M0197) | C6: 583-60-8 | D6: ='A1 = fluorenone'!A23 -> 2-methylcyclohexanone(trans) | E6: aliphaticcyclo | F6: 0 | G6: O=C1[C@@H](C)CCCC1 | H6: 273 | I6: ='A1 = fluorenone'!Q23 -> -0.52851761 | J6: =I6+$L$22 -> -2.2778374 | K6: ='A1 = fluorenone'!R23 -> 0.030599363 | Q6: =J6 -> -2.2778374 | R6: =K6 -> 0.030599363 | S6: =EXP(-Q6/1.99/H6*1000) -> 66.20973 | V6: SDBS(No.:1437) | W6: SDBS(No.:709) | X6: this work
A7: D99(cis) | B7: TCI(M0197) | C7: 583-60-8 | D7: ='A1 = fluorenone'!A24 -> 2-methylcyclohexanone(cis) | E7: aliphaticcyclo | F7: 0 | G7: O=C1[C@H](C)CCCC1 | H7: 273 | I7: ='A1 = fluorenone'!Q24 -> -0.19387865 | J7: =I7+$L$22 -> -1.9431984 | K7: ='A1 = fluorenone'!R24 -> 0.054387204 | Q7: =J7 -> -1.9431984 | R7: =K7 -> 0.054387204 | S7: =EXP(-Q7/1.99/H7*1000) -> 35.760921 | V7: SDBS(No.:1437) | W7: SDBS(No.:708) | X7: this work
A8: A99 | B8: TCI(B0098) | C8: 614-16-4 | D8: ='A1 = fluorenone'!A25 -> Benzoylacetonitrile | F8: 0 | G8: O=C(c1ccccc1)CC#N | H8: 273 | I8: ='A1 = fluorenone'!Q25 -> -0.3636398 | J8: =I8+$L$22 -> -2.1129596 | K8: ='A1 = fluorenone'!R25 -> 0.014362019 | Q8: =J8 -> -2.1129596 | R8: =M8 -> 0 | S8: =EXP(-Q8/1.99/H8*1000) -> 48.878419 | V8: SDBS(No.:6287) | W8: CAS | X8: this work
A9: D10 | B9: TCI(D4149) | C9: 4255-62-3 | D9: ='A1 = fluorenone'!A37 -> 4,4-dimethylcyclohexanone | E9: aliphaticcyclo | F9: 0 | G9: O=C1[13CH2]CC(C)(C)CC1 | H9: 273 | I9: ='A1 = fluorenone'!Q37 -> -0.35264328 | J9: =I9+$L$22 -> -2.101963 | K9: ='A1 = fluorenone'!R37 -> 0.014487071 | L9: ='A1 = benzophenone'!Q22 -> -2.2408885 | M9: ='A1 = benzophenone'!R22 -> 0.073588328 | Q9: =J9 -> -2.101963 | R9: =K9 -> 0.014487071 | S9: =EXP(-Q9/1.99/H9*1000) -> 47.898999 | V9: Bolli, Martin H., et al. "Novel S1P1 Receptor Agonists-Part 2: From Bicyclo [3.1. 0] hexane-Fused Thiophenes to Isobutyl Substituted Thiophenes." Journal of Medicinal Chemistry 57.1 (2014): 78-97. | W9: Uyanik, Muhammet, Matsujiro Akakura, and Kazuaki Ishihara. "2-Iodoxybenzenesulfonic acid as an extremely active catalyst for the selective oxidation of alcohols to aldehydes, ketones, carboxylic acids, and enones with oxone." Journal of the American Chemical Society 131.1 (2009): 251-262. | X9: this work
A10: B5 | B10: TCI(I0649) | C10: 615-13-4 | D10: ='A1 = fluorenone'!A42 -> 2-indanone | E10: arylcyclo | F10: 0 | G10: O=C1[13CH2]c2ccccc2C1 | H10: 273 | I10: ='A1 = fluorenone'!Q42 -> -0.35246825 | J10: =I10+$L$22 -> -2.101788 | K10: ='A1 = fluorenone'!R42 -> 0.033098067 | L10: ='A1 = benzophenone'!Q3 -> -2.5103753 | M10: ='A1 = benzophenone'!$R$3 -> 0.094668015 | Q10: =J10 -> -2.101788 | R10: =K10 -> 0.033098067 | S10: =EXP(-Q10/1.99/H10*1000) -> 47.883569 | V10: Phatake, Ravindra S., and Chepuri V. Ramana. "Oxone–acetone mediated Wacker-type oxidation of benzo-fused olefins." Tetrahedron Letters 56.25 (2015): 3868-3871. | W10: SDBS(No.:6339) | X10: this work
A11: D11(trans) | B11: TCI(B1074) | C11: 98-53-3 | D11: ='A1 = fluorenone'!A52 -> 4-tert-butylcyclohexanone (trans) | E11: aliphaticcyclo | F11: 0 | G11: O=C1[13CH2]C[C@@H](C(C)(C)C)CC1 | H11: 273 | I11: ='A1 = fluorenone'!Q52 -> -0.53481706 | J11: =I11+$L$22 -> -2.2841368 | K11: ='A1 = fluorenone'!R52 -> 0.0054794785 | L11: ='A1 = benzophenone'!Q13 -> -2.5596575 | M11: ='A1 = benzophenone'!R13 -> 0.019986691 | Q11: =J11 -> -2.2841368 | R11: =K11 -> 0.0054794785 | S11: =EXP(-Q11/1.99/H11*1000) -> 66.981928 | V11: SDBS(No.:843) | W11: Maegawa, Tomohiro, et al. "Efficient and practical arene hydrogenation by heterogeneous catalysts under mild conditions." Chemistry–A European Journal 15.28 (2009): 6953-6963. | X11: this work
A12: D11(cis) | B12: TCI(B1074) | C12: 98-53-3 | D12: ='A1 = fluorenone'!A53 -> 4-tert-butylcyclohexanone (cis) | E12: aliphaticcyclo | F12: 0 | G12: O=C1[13CH2]C[C@H](C(C)(C)C)CC1 | H12: 273 | I12: ='A1 = fluorenone'!Q53 -> 0.16837852 | J12: =I12+$L$22 -> -1.5809412 | K12: ='A1 = fluorenone'!R53 -> 0.0054794785 | L12: ='A1 = benzophenone'!Q14 -> -1.7227799 | M12: ='A1 = benzophenone'!R14 -> 0.019986691 | Q12: =J12 -> -1.5809412 | R12: =K12 -> 0.0054794785 | S12: =EXP(-Q12/1.99/H12*1000) -> 18.357661 | V12: SDBS(No.:843) | W12: Maegawa, Tomohiro, et al. "Efficient and practical arene hydrogenation by heterogeneous catalysts under mild conditions." Chemistry–A European Journal 15.28 (2009): 6953-6963. | X12: this work
A13: A4 | B13: TCI(N0111) | C13: 100-19-6 | D13: ='A1 = fluorenone'!A54 -> 4'-nitroacetophenone | E13: acetophenone | F13: 0 | G13: O=C(C)c1ccc([N+]([O-])=O)cc1 | H13: 273 | I13: ='A1 = fluorenone'!Q54 -> -0.26912766 | J13: =I13+$L$22 -> -2.0184474 | K13: ='A1 = fluorenone'!R54 -> 0.011994637 | L13: ='A1 = benzophenone'!Q44 -> -1.8901003 | M13: ='A1 = benzophenone'!R44 -> 0.06033477 | Q13: =J13 -> -2.0184474 | R13: =K13 -> 0.011994637 | S13: =EXP(-Q13/1.99/H13*1000) -> 41.073657 | T13: 0.78 | V13: SDBS(No.:1014) | W13: Yang, Yongsheng, et al. "Formal hydration of non-activated terminal olefins using tandem catalysts." Chemical Communications 50.20 (2014): 2608-2611. | X13: this work
A14: D8(cis) | B14: TCI(M0198) | C14: 591-24-2 | D14: ='A1 = fluorenone'!A64 -> 3-methylcyclohexanone (cis) | E14: aliphaticcyclo | F14: 0 | G14: O=C1C[C@H](C)CCC1 | H14: 273 | I14: ='A1 = fluorenone'!Q64 -> -0.35410211 | J14: =I14+$L$22 -> -2.1034219 | K14: ='A1 = fluorenone'!R64 -> 0.017305498 | L14: ='A1 = benzophenone'!Q32 -> -2.4035 | M14: ='A1 = benzophenone'!R32 -> 0.034283298 | Q14: =J14 -> -2.1034219 | R14: =K14 -> 0.017305498 | S14: =EXP(-Q14/1.99/H14*1000) -> 48.027794 | V14: SDBS(No.:3734) | W14: Maegawa, Tomohiro, et al. "Efficient and practical arene hydrogenation by heterogeneous catalysts under mild conditions." Chemistry–A European Journal 15.28 (2009): 6953-6963. | X14: this work
A15: D8(trans) | B15: TCI(M0198) | C15: 591-24-2 | D15: ='A1 = fluorenone'!A65 -> 3-methylcyclohexanone (trans) | E15: aliphaticcyclo | F15: 0 | G15: O=C1C[C@@H](C)CCC1 | H15: 273 | I15: ='A1 = fluorenone'!Q65 -> 0.24650066 | J15: =I15+$L$22 -> -1.5028191 | K15: ='A1 = fluorenone'!R65 -> 0.017305498 | L15: ='A1 = benzophenone'!Q33 -> -1.7603932 | M15: ='A1 = benzophenone'!R33 -> 0.034283298 | Q15: =J15 -> -1.5028191 | R15: =K15 -> 0.017305498 | S15: =EXP(-Q15/1.99/H15*1000) -> 15.898856 | V15: SDBS(No.:3734) | W15: Maegawa, Tomohiro, et al. "Efficient and practical arene hydrogenation by heterogeneous catalysts under mild conditions." Chemistry–A European Journal 15.28 (2009): 6953-6963. | X15: this work
A16: C3 | B16: TCI(P1336) | C16: 1817-57-8 | D16: ='A1 = fluorenone'!A66 -> 4-phenyl-3-butyn-2-one | E16: chain | F16: 0 | G16: O=C(C)C#Cc1ccccc1 | H16: 273 | I16: ='A1 = fluorenone'!Q66 -> -0.057300518 | J16: =I16+$L$22 -> -1.8066203 | K16: ='A1 = fluorenone'!R66 -> 0.014920035 | L16: ='A1 = benzophenone'!Q49 -> -1.8648138 | M16: ='A1 = benzophenone'!R49 -> 0.030251134 | Q16: =J16 -> -1.8066203 | R16: =K16 -> 0.014920035 | S16: =EXP(-Q16/1.99/H16*1000) -> 27.811667 | V16: SDBS(No.:23711) | W16: Hashmi, A. Stephen K., et al. "Regioselectivity switch: gold (I)-catalyzed oxidative rearrangement of propargyl alcohols to 1, 3-diketones." The Journal of Organic Chemistry 77.17 (2012): 7761-7767. | X16: this work
A17: A9 | B17: Aldrich(N9381) | C17: 121-89-1 | D17: ='A1 = fluorenone'!A71 -> 3'-nitroacetophenone | E17: acetophenone | F17: 0 | G17: O=C(C)c1cc([N+]([O-])=O)ccc1 | H17: 273 | I17: ='A1 = fluorenone'!Q71 -> -0.045735601 | J17: =I17+$L$22 -> -1.7950553 | K17: ='A1 = fluorenone'!R71 -> 0.0086069326 | Q17: =J17 -> -1.7950553 | R17: =K17 -> 0.0086069326 | S17: =EXP(-Q17/1.99/H17*1000) -> 27.22588 | V17: SDBS(No.:1021) | W17: Scifinder (Spectrum IDWSLH_2017_019461, Spectral data were obtained from John Wiley & Sons, Inc.) | X17: this work
A18: B6 | B18: TCI(T1167) | C18: 530-93-8 | D18: ='A1 = fluorenone'!A76 -> 2-tetralone | E18: arylcyclo | F18: 0 | G18: O=C1Cc2ccccc2CC1 | H18: 273 | I18: ='A1 = fluorenone'!Q76 -> 0.023753801 | J18: =I18+$L$22 -> -1.7255659 | K18: ='A1 = fluorenone'!R76 -> 0.0058431032 | L18: ='A1 = benzophenone'!Q54 -> -1.7623652 | M18: ='A1 = benzophenone'!$R$54 -> 0.10254472 | Q18: =J18 -> -1.7255659 | R18: =K18 -> 0.0058431032 | S18: =EXP(-Q18/1.99/H18*1000) -> 23.95695 | V18: Wang, Zhi-Ming, et al. "Ruthenium (IV) porphyrin catalyzed highly selective oxidation of internal alkenes into ketones with Cl2pyNO as terminal oxidant." Tetrahedron Letters 55.10 (2014): 1736-1739. | W18: Li, Huaifeng, et al. "Selective catalytic hydrogenation of arenols by a well-defined complex of ruthenium and phosphorus–nitrogen PN3–pincer ligand containing a phenanthroline backbone." ACS Catalysis 7.7 (2017): 4446-4450. | X18: this work
A19: D9(trans) | B19: TCI(M0199) | C19: 589-92-4 | D19: ='A1 = benzophenone'!A20 -> 4-methylcyclohexanone (trans) | E19: aliphaticcyclo | F19: 0 | G19: O=C1[13CH2]C[C@@H](C)CC1 | H19: 273 | L19: ='A1 = benzophenone'!Q20 -> -2.5316083 | M19: ='A1 = benzophenone'!R20 -> 0.057619887 | Q19: =L19 -> -2.5316083 | R19: =M19 -> 0.057619887 | S19: =EXP(-Q19/1.99/H19*1000) -> 105.63026 | V19: SDBS(No.:5761) | W19: Maegawa, Tomohiro, et al. "Efficient and practical arene hydrogenation by heterogeneous catalysts under mild conditions." Chemistry–A European Journal 15.28 (2009): 6953-6963. | X19: this work
A20: D9(cis) | B20: TCI(M0199) | C20: 589-92-4 | D20: ='A1 = benzophenone'!A21 -> 4-methylcyclohexanone (cis) | E20: aliphaticcyclo | F20: 0 | G20: O=C1[13CH2]C[C@H](C)CC1 | H20: 273 | L20: ='A1 = benzophenone'!Q21 -> -1.7285999 | M20: ='A1 = benzophenone'!R21 -> 0.057619887 | Q20: =L20 -> -1.7285999 | R20: =M20 -> 0.057619887 | S20: =EXP(-Q20/1.99/H20*1000) -> 24.091113 | V20: SDBS(No.:5761) | W20: Maegawa, Tomohiro, et al. "Efficient and practical arene hydrogenation by heterogeneous catalysts under mild conditions." Chemistry–A European Journal 15.28 (2009): 6953-6963. | X20: this work
A21: D4 | B21: TCI(C0489) | C21: 108-94-1 | D21: ='A1 = benzophenone'!A39 -> cyclohexanone | E21: aliphaticcyclo | F21: 0 | G21: O=C1[13CH2]CCCC1 | H21: 273 | L21: ='A1 = benzophenone'!Q39 -> -2.0835535 | M21: ='A1 = benzophenone'!R39 -> 0.058642057 | Q21: =L21 -> -2.0835535 | R21: =M21 -> 0.058642057 | S21: =EXP(-Q21/1.99/H21*1000) -> 46.30306 | V21: SDBS(No.:571) | W21: SDBS(No.:581) | X21: this work
A22: B7 | B22: TCI(F0021) | C22: 486-25-9 | D22: ='A1 = benzophenone'!A59 -> 9-fluorenone | E22: arylcyclo | F22: 1 | G22: O=C1[13c]2ccccc2c3ccccc13 | H22: 273 | I22: 0 | J22: =I22+$L$22 -> -1.7493197 | K22: 0 | L22: ='A1 = benzophenone'!Q59 -> -1.7493197 | M22: ='A1 = benzophenone'!$R$59 -> 0.018329314 | Q22: =J22 -> -1.7493197 | R22: =K22 -> 0 | S22: =EXP(-Q22/1.99/H22*1000) -> 25.027676 | U22: 104.82 | V22: SDBS(No.:2223) | W22: SDBS(No.:4909) | X22: this work
A23: D1(cis) | B23: TCI(B6029) | C23: 30830-27-4 | D23: 3-(benzyloxy)cyclobutanone(cis) | E23: aliphaticcyclo | F23: 1 | G23: O=C1[13CH2][C@H](OCc2ccccc2)C1 | H23: 273 | L23: ='A1 = benzophenone'!Q69 -> -1.9691263 | M23: ='A1 = benzophenone'!R69 -> 0.037798738 | Q23: =L23 -> -1.9691263 | R23: =M23 -> 0.037798738 | S23: =EXP(-Q23/1.99/H23*1000) -> 37.509017 | V23: McConathy, Jonathan, et al. "Improved synthesis of anti-[18F] FACBC: improved preparation of labeling precursor and automated radiosynthesis." Applied Radiation and Isotopes 58.6 (2003): 657-666. | W23: Franck, Dominic, et al. "Investigations into the synthesis, radiofluorination and conjugation of a new [18F] fluorocyclobutyl prosthetic group and its in vitro stability using a tyrosine model system." Bioorganic & medicinal chemistry 21.3 (2013): 643-652. | X23: this work
A24: D1(trans) | B24: TCI(B6029) | C24: 30830-27-4 | D24: 3-(benzyloxy)cyclobutanone(trans) | E24: aliphaticcyclo | F24: 1 | G24: O=C1[13CH2][C@@H](OCc2ccccc2)C1 | H24: 273 | L24: ='A1 = benzophenone'!Q70 -> -0.91197171 | M24: ='A1 = benzophenone'!R70 -> 0.037798738 | Q24: =L24 -> -0.91197171 | R24: =M24 -> 0.037798738 | S24: =EXP(-Q24/1.99/H24*1000) -> 5.358431 | V24: McConathy, Jonathan, et al. "Improved synthesis of anti-[18F] FACBC: improved preparation of labeling precursor and automated radiosynthesis." Applied Radiation and Isotopes 58.6 (2003): 657-666. | W24: Confirmed from the Enamine database spectrum available on SciFinder. | X24: this work
A25: A11 | B25: TCI(T1546） | C25: 349-76-8 | D25: ='A1 = benzophenone'!A71 -> 3'-(trifluoromethyl)acetophenone | E25: acetophenone | F25: 0 | G25: O=C(C)c1cc(C(F)(F)F)ccc1 | H25: 273 | L25: ='A1 = benzophenone'!Q71 -> -1.5841979 | M25: ='A1 = benzophenone'!$R$71 -> 0.02876503 | Q25: =L25 -> -1.5841979 | R25: =M25 -> 0.02876503 | S25: =EXP(-Q25/1.99/H25*1000) -> 18.468038 | T25: 0.43 | V25: SDBS(No.:21485) | W25: Bigler, Raphael, Raffael Huber, and Antonio Mezzetti. "Highly enantioselective transfer hydrogenation of ketones with chiral (NH) 2P2 macrocyclic iron (II) complexes." Angewandte Chemie 127.17 (2015): 5260-5263. | X25: this work
A26: E4 | B26: TCI(A0719) | C26: 700-58-3 | D26: ='A1 = benzophenone'!A76 -> 2-adamantanone | E26: polycyclic | F26: 0 | G26: C1C2CC3CC1C[13CH](C2)C3=O | H26: 273 | I26: ='A1 = fluorenone'!Q81 -> 0.26610523 | J26: =I26+$L$22 -> -1.4832145 | K26: ='A1 = fluorenone'!R81 -> 0.030459074 | L26: ='A1 = benzophenone'!Q76 -> -1.4704738 | M26: ='A1 = benzophenone'!R76 -> 0.012088341 | Q26: =L26 -> -1.4704738 | R26: =M26 -> 0.012088341 | S26: =EXP(-Q26/1.99/H26*1000) -> 14.979895 | V26: SDBS(No.:403) | W26: SDBS(No.:25) | X26: this work
A27: A6 | B27: TCI(T1784) | C27: 709-63-7 | D27: ='A1 = benzophenone'!A81 -> 4'-(trifluoromethyl)acetophenone | E27: acetophenone | F27: 0 | G27: O=C(C)c1ccc(C(F)(F)F)cc1 | H27: 273 | L27: ='A1 = benzophenone'!Q81 -> -1.4634051 | M27: ='A1 = benzophenone'!R81 -> 0.059895933 | Q27: =L27 -> -1.4634051 | R27: =M27 -> 0.059895933 | S27: =EXP(-Q27/1.99/H27*1000) -> 14.786249 | T27: 0.54 | V27: SDBS(No.:23190) | W27: Peng, Dongjie, Mintao Zhang, and Zheng Huang. "A General, Practical Triethylborane‐Catalyzed Reduction of Carbonyl Functions to Alcohols." Chemistry–A European Journal 21.42 (2015): 14737-14741. | X27: this work
A28: C8 | B28: TCI(F0970) | C28: 2836-82-0 | D28: ='A1 = benzophenone'!A101 -> 2-fluorophenylacetone | E28: acetophenone | F28: 0 | G28: O=C(C)Cc1c(F)cccc1 | H28: 273 | L28: ='A1 = benzophenone'!Q101 -> -1.1844709 | M28: ='A1 = benzophenone'!R101 -> 0.051868392 | Q28: =L28 -> -1.1844709 | R28: =M28 -> 0.051868392 | S28: =EXP(-Q28/1.99/H28*1000) -> 8.8486236 | V28: Fu, Wai Chung, Zhongyuan Zhou, and Fuk Yee Kwong. "Preparation of a Highly Congested Carbazoyl-Derived P, N-Type Phosphine Ligand for Acetone Monoarylations." Organometallics 35.10 (2016): 1553-1558. | W28: Liu, Weiping, et al. "A General Regioselective Synthesis of Alcohols by Cobalt‐Catalyzed Hydrogenation of Epoxides." Angewandte Chemie 132.28 (2020): 11417-11420. | X28: this work
A29: C2 | B29: TCI(B0405) | C29: 2550-26-7 | D29: ='A1 = benzophenone'!A113 -> 4-phenyl-2-butanone | E29: chain | F29: 0 | G29: O=C(C)CCc1ccccc1 | H29: 273 | I29: ='A1 = fluorenone'!Q86 -> 0.60956896 | J29: =I29+$L$22 -> -1.1397508 | K29: ='A1 = fluorenone'!R86 -> 0.011855117 | L29: ='A1 = benzophenone'!Q113 -> -0.99204607 | M29: ='A1 = benzophenone'!R113 -> 0.30242809 | Q29: =J29 -> -1.1397508 | R29: =K29 -> 0.011855117 | S29: =EXP(-Q29/1.99/H29*1000) -> 8.1494088 | V29: SDBS(No.:13611) | W29: SDBS(No.:1443) | X29: this work
A30: C4 | B30: TCI(D1157) | C30: 5436-21-5 | D30: ='A1 = benzophenone'!A123 -> 1,1-dimethoxy-3-butanone | E30: chain | F30: 0 | G30: O=C(C)CC(OC)OC | H30: 273 | L30: ='A1 = benzophenone'!Q123 -> -0.8821075 | M30: ='A1 = benzophenone'!$R$123 -> 0.0090478732 | Q30: =L30 -> -0.8821075 | R30: =M30 -> 0.0090478732 | S30: =EXP(-Q30/1.99/H30*1000) -> 5.0718214 | V30: SDBS(No.:3407) | W30: Heathcock, Clayton H., Syunichi Kiyooka, and Todd A. Blumenkopf. "Acyclic stereoselection. 22. Diastereofacial selectivity in the Lewis acid mediated reactions of allylsilanes with chiral aldehydes and enones." The Journal of Organic Chemistry 49.22 (1984): 4214-4223. | X30: this work
A31: C6 | B31: TCI(C3585) | C31: 6004-60-0 | D31: ='A1 = benzophenone'!A128 -> 1-cyclopentylethanone | E31: chain | F31: 0 | G31: O=C(C)C1CCCC1 | H31: 273 | I31: ='A1 = fluorenone'!Q98 -> 0.78543763 | J31: =I31+$L$22 -> -0.96388212 | K31: ='A1 = fluorenone'!R98 -> 0.016949302 | L31: ='A1 = benzophenone'!Q128 -> -0.87412513 | M31: ='A1 = benzophenone'!R128 -> 0.046474729 | Q31: =L31 -> -0.87412513 | R31: =M31 -> 0.046474729 | S31: =EXP(-Q31/1.99/H31*1000) -> 4.997845 | V31: Schmidt, Gunther, et al. "Practical synthesis of a S1P receptor 1 agonist via a guareschi–thorpe reaction." Organic Process Research & Development 20.9 (2016): 1637-1646. | W31: Hinkens, D. M.; Midland, M. M. Investigation of Cyclization Reactions of Dicyclohexyl-6-iodo- and -6-tosylhexenylborane. A Facile Radical Cyclization Diverted to a Rearrangement−Cyclization with Base. J. Org. Chem. 2009, 74(11), 4143–4148. | X31: this work
A32: B2 | B32: TCI(C1644) | C32: 42348-86-7 | D32: ='A1 = benzophenone'!A133 -> 5-chloro-1-indanone | E32: arylcyclo | F32: 0 | G32: O=C1c2ccc(Cl)cc2CC1 | H32: 273 | L32: ='A1 = benzophenone'!Q133 -> -0.81199078 | M32: ='A1 = benzophenone'!R133 -> 0.0078406645 | Q32: =L32 -> -0.81199078 | R32: =M32 -> 0.0078406645 | S32: =EXP(-Q32/1.99/H32*1000) -> 4.4577126 | V32: Chen, Peng-hao, et al. "Rh-catalyzed reagent-free ring expansion of cyclobutenones and benzocyclobutenones." Chemical science 6.10 (2015): 5440-5445. | W32: Arp, Forrest O., and Gregory C. Fu. "Catalytic enantioselective Negishi reactions of racemic secondary benzylic halides." Journal of the American Chemical Society 127.30 (2005): 10482-10483. | X32: this work
A33: C5 | B33: TCI(N0293) | C33: 821-55-6 | D33: ='A1 = benzophenone'!A138 -> 2-nonanone | E33: chain | F33: 0 | G33: CCCCCCCC(=O)C | H33: 273 | L33: ='A1 = benzophenone'!$Q$138 -> -0.79591068 | M33: ='A1 = benzophenone'!$R$138 -> 0.0083426149 | N33: ='A1=dibenzosuberone'!Q3 -> -2.1508108 | O33: =N33++$L$77 -> -1.1280136 | P33: ='A1=dibenzosuberone'!R3 -> 0.046586136 | Q33: =L33 -> -0.79591068 | R33: =M33 -> 0.0083426149 | S33: =EXP(-Q33/1.99/H33*1000) -> 4.3277036 | V33: SDBS(No.:2134) | W33: SDBS(No.:6584) | X33: this work
A34: D13(trans) | B34: TCI(T0602) | C34: 873-94-9 | D34: ='A1 = benzophenone'!A148 -> 3,3,5-trimethylcyclohexanone(trans) | E34: aliphaticcyclo | F34: 0 | G34: O=C1CC(C)(C)C[C@@H](C)C1 | H34: 273 | I34: ='A1 = fluorenone'!Q96 -> 0.46636494 | J34: =I34+$L$22 -> -1.2829548 | K34: ='A1 = fluorenone'!R96 -> 0.069694411 | L34: ='A1 = benzophenone'!Q148 -> -1.0930328 | M34: ='A1 = benzophenone'!R148 -> 0.0058324499 | Q34: =L34 -> -1.0930328 | R34: =M34 -> 0.0058324499 | S34: =EXP(-Q34/1.99/H34*1000) -> 7.477895 | V34: SDBS(No.:6517) | W34: SDBS(No.:6556) | X34: this work
A35: D13(cis) | B35: TCI(T0602) | C35: 873-94-9 | D35: ='A1 = benzophenone'!A149 -> 3,3,5-trimethylcyclohexanone(cis) | E35: aliphaticcyclo | F35: 0 | G35: O=C1CC(C)(C)C[C@H](C)C1 | H35: 273 | I35: ='A1 = fluorenone'!Q97 -> 1.1104787 | J35: =I35+$L$22 -> -0.63884104 | K35: ='A1 = fluorenone'!R97 -> 0.069694411 | L35: ='A1 = benzophenone'!Q149 -> -0.18361162 | M35: ='A1 = benzophenone'!R149 -> 0.0058324499 | Q35: =L35 -> -0.18361162 | R35: =M35 -> 0.0058324499 | S35: =EXP(-Q35/1.99/H35*1000) -> 1.4021053 | V35: SDBS(No.:6517) | W35: SDBS(No.:6555) | X35: this work
A36: A5 | B36: TCI( C0033) | C36: 99-91-2 | D36: ='A1 = benzophenone'!A150 -> 4'-chloroacetophenone | E36: acetophenone | F36: 0 | G36: O=C(C)c1ccc(Cl)cc1 | H36: 273 | L36: ='A1 = benzophenone'!Q150 -> -0.7904736 | M36: ='A1 = benzophenone'!R150 -> 0.043574911 | Q36: =L36 -> -0.7904736 | R36: =M36 -> 0.043574911 | S36: =EXP(-Q36/1.99/H36*1000) -> 4.2846077 | T36: 0.23 | V36: SDBS(No.:2376) | W36: SDBS(Np.:6159) | X36: this work
A37: A17 | B37: TCI(D6091) | C37: 938-16-9 | D37: ='A1 = benzophenone'!A155 -> 2,2-dimethyl-1-phenylpropan-1-one | E37: acetophenone | F37: 0 | G37: O=C(C(C)(C)C)c1ccccc1 | H37: 273 | L37: ='A1 = benzophenone'!Q155 -> -0.76726929 | M37: ='A1 = benzophenone'!R155 -> 0.015932873 | Q37: =L37 -> -0.76726929 | R37: =M37 -> 0.015932873 | S37: =EXP(-Q37/1.99/H37*1000) -> 4.1054555 | V37: Zhu, Yingguang, Baoguo Zhao, and Yian Shi. "Highly efficient Cu (I)-catalyzed oxidation of alcohols to ketones and aldehydes with diaziridinone." Organic letters 15.5 (2013): 992-995. | W37: Kuriyama, Masami, Rumiko Shimazawa, and Ryuichi Shirai. "Efficient 1, 2-Addition of Aryl-and Alkenylboronic Acids to Aldehydes Catalyzed by the Palladium/Thioether− Imidazolinium Chloride System." The Journal of Organic Chemistry 73.4 (2008): 1597-1600. | X37: this work
A38: A10 | B38: TCI(C0096) | C38: 99-02-5 | D38: ='A1 = benzophenone'!A160 -> 3'-chloroacetophenone | E38: acetophenone | F38: 0 | G38: O=C(C)c1cc(Cl)ccc1 | H38: 273 | L38: ='A1 = benzophenone'!$Q$160 -> -0.74511058 | M38: ='A1 = benzophenone'!$R$160 -> 0.075521608 | Q38: =L38 -> -0.74511058 | R38: =M38 -> 0.075521608 | S38: =EXP(-Q38/1.99/H38*1000) -> 3.9413726 | T38: 0.37 | V38: SDBS(No.:2383) | W38: Jung, Thais Cordeiro, Gilles Argouarch, and Pierre van De Weghe. "Cyclopentadienyliron dicarbonyl dimer: A simple tool for the hydrosilylation of aldehydes and ketones under air." Catalysis Communications 78 (2016): 52-54. | X38: this work
A39: B10 | B39: TCI(D1791) | C39: 2222-33-5 | D39: ='A1 = benzophenone'!A165 -> dibenzosuberenone | E39: arylcyclo | F39: 0 | G39: O=C1[13c]2ccccc2C=Cc3ccccc13 | H39: 273 | L39: ='A1 = benzophenone'!Q165 -> -0.5707523 | M39: ='A1 = benzophenone'!R165 -> 0.0075487168 | Q39: =L39 -> -0.5707523 | R39: =M39 -> 0.0075487168 | S39: =EXP(-Q39/1.99/H39*1000) -> 2.8593285 | V39: SDBS(No.:12961) | W39: Confirmed from the Sigma-Aldrich database spectrum available on SciFinder. | X39: this work
A40: E2(endo) | B40: TCI(N0511) | C40: 497-38-1 | D40: ='A1 = benzophenone'!A175 -> 2-norbornanone (endo) | E40: polycyclic | F40: 0 | G40: O=C1[C@@H](C2)CCC2C1 | H40: 273 | L40: ='A1 = benzophenone'!Q175 -> -0.89850456 | M40: ='A1 = benzophenone'!R175 -> 0.021760666 | Q40: =L40 -> -0.89850456 | R40: =M40 -> 0.021760666 | S40: =EXP(-Q40/1.99/H40*1000) -> 5.2272335 | V40: SDBS(No.:13580) | W40: SDBS(No.:21209) | X40: this work
...

Sheet A1 = fluorenone
B1: Starting amount [mmol] | E1: Endpoint ratio (from 1H-NMR integration) | O1: confidence interval | Q1: ΔΔG [kcal/mol]
A2: A2 | B2: A1 | C2: A2 | D2: NaBH4 | E2: A1 | F2: A2 | G2: alcohol1 | H2: alcohol2 | I2: [A1]f / [A1]0 | J2: [A2]f / [A2]0 | K2: -ln([A1]f / [A1]0) | L2: -ln([A2]f / [A2]0) | M2: LINEST analysis | O2: ± 1σ | P2: % | Q2: value | R2: ±68% (1σ) | S2: note
A3: 1-chloropinacolin | B3: 0.2 | C3: 0.2 | D3: 0.04 | E3: 1 | F3: 0.52 | G3: 0.17 | H3: 0.619 | I3: =E3/(E3+G3) -> 0.85470085 | J3: =F3/(F3+H3) -> 0.45654083 | K3: =-LN(I3) -> 0.15700375 | L3: =-LN(J3) -> 0.78407715 | M3: {=LINEST(L3:L5,K3:K5,FALSE,TRUE)} -> 4.7967195 | N3: 0 | O3: =TINV(0.32,N6)*M4 -> 0.12340848 | P3: =O3*100/M3 -> 2.5727684 | Q3: =-1.99*273*LN(M3)/1000 -> -0.85181055 | R3: =ABS(1.99*273*O3/M3/1000) -> 0.013977079
B4: 0.2 | C4: 0.2 | D4: 0.08 | E4: 1 | F4: 0.448 | G4: 0.223 | H4: 0.726 | I4: =E4/(E4+G4) -> 0.81766149 | J4: =F4/(F4+H4) -> 0.38160136 | K4: =-LN(I4) -> 0.20130686 | L4: =-LN(J4) -> 0.96337877 | M4: 0.094091574 | N4: #N/A
B5: 0.2 | C5: 0.2 | D5: 0.12 | E5: 1 | F5: 0.53 | G5: 0.183 | H5: 0.626 | I5: =E5/(E5+G5) -> 0.84530854 | J5: =F5/(F5+H5) -> 0.45847751 | K5: =-LN(I5) -> 0.16805358 | L5: =-LN(J5) -> 0.77984404 | M5: 0.99923103 | N5: 0.028758276
M6: 2598.8857 | N6: 2
M7: 2.1493783 | N7: 0.0016540768
A8: 2,2,2-trifluoroacetophenone | B8: 0.2 | C8: 0.2 | D8: 0.04 | E8: 1.544 | F8: 1 | G8: 0.606 | H8: 1.15 | I8: =E8/(E8+G8) -> 0.71813953 | J8: =F8/(F8+H8) -> 0.46511628 | K8: =-LN(I8) -> 0.33109139 | L8: =-LN(J8) -> 0.76546784 | M8: {=LINEST(L8:L10,K8:K10,FALSE,TRUE)} -> 2.8942211 | N8: 0 | O8: =TINV(0.32,N11)*M9 -> 0.33233658 | P8: =O8*100/M8 -> 11.482764 | Q8: =-1.99*273*LN(M8)/1000 -> -0.57734173 | R8: =ABS(1.99*273*O8/M8/1000) -> 0.062382414
B9: 0.2 | C9: 0.2 | D9: 0.08 | E9: 2.045 | F9: 1 | G9: 1.111 | H9: 2.156 | I9: =E9/(E9+G9) -> 0.64797212 | J9: =F9/(F9+H9) -> 0.31685678 | K9: =-LN(I9) -> 0.43390761 | L9: =-LN(J9) -> 1.1493054 | M9: 0.25338673 | N9: #N/A
B10: 0.2 | C10: 0.2 | D10: 0.12 | E10: 3.692 | F10: 1 | G10: 2.977 | H10: 5.669 | I10: =E10/(E10+G10) -> 0.55360624 | J10: =F10/(F10+H10) -> 0.14994752 | K10: =-LN(I10) -> 0.59130161 | L10: =-LN(J10) -> 1.8974699 | M10: 0.98490173 | N10: 0.20389917
M11: 130.46549 | N11: 2
M12: 5.4240863 | N12: 0.083149746
A13: 1,4-Cyclohexanedion monoethyleneketal | B13: 0.2 | C13: 0.2 | D13: 0.02 | E13: 1 | F13: =3.5536/4 -> 0.8884 | G13: 0.0776 | H13: 0.2142 | I13: =E13/(E13+G13) -> 0.92798812 | J13: =F13/(F13+H13) -> 0.80573191 | K13: =-LN(I13) -> 0.074736346 | L13: =-LN(J13) -> 0.21600421 | M13: {=LINEST(L13:L16,K13:K16,FALSE,TRUE)} -> 2.5914183 | N13: 0 | O13: =TINV(0.32,N16)*M14 -> 0.042934292 | P13: =O13*100/M13 -> 1.6567874 | Q13: =-1.99*273*LN(M13)/1000 -> -0.51730459 | R13: =ABS(1.99*273*O13/M13/1000) -> 0.0090008289
A14: dibenzosuberone-2 | B14: 0.2 | C14: 0.2 | D14: 0.04 | E14: 1 | F14: =3.0628/4 -> 0.7657 | G14: 0.1637 | H14: 0.3793 | I14: =E14/(E14+G14) -> 0.85932801 | J14: =F14/(F14+H14) -> 0.66873362 | K14: =-LN(I14) -> 0.15160458 | L14: =-LN(J14) -> 0.40236947 | M14: 0.036111748 | N14: #N/A
A15: dibenzosuberone-3 | B15: 0.2 | C15: 0.2 | D15: 0.06 | E15: 1 | F15: =2.5441/4 -> 0.636025 | G15: 0.2557 | H15: 0.5149 | I15: =E15/(E15+G15) -> 0.79636856 | J15: =F15/(F15+H15) -> 0.55262072 | K15: =-LN(I15) -> 0.22769319 | L15: =-LN(J15) -> 0.59308338 | M15: 0.99941778 | N15: 0.015632222
B16: 0.2 | C16: 0.2 | D16: 0.08 | E16: 1 | F16: =2.149/4 -> 0.53725 | G16: 0.3869 | H16: 0.7022 | I16: =E16/(E16+G16) -> 0.72103252 | J16: =F16/(F16+H16) -> 0.43345839 | K16: =-LN(I16) -> 0.32707104 | L16: =-LN(J16) -> 0.83595948 | M16: 5149.6535 | N16: 3
M17: 1.258402 | N17: 0.00073309906
A18: 2-methylcyclohexanone | B18: 0.2 | C18: 0.2 | D18: 0.02 | E18: 1 | F18: =1.43/3 -> 0.47666667 | G18: 0.14 | H18: =0.0378+0.0717 -> 0.1095 | I18: =E18/(E18+G18) -> 0.87719298 | J18: =F18/(F18+H18) -> 0.81319306 | K18: =-LN(I18) -> 0.13102826 | L18: =-LN(J18) -> 0.20678673 | M18: {=LINEST(L18:L21,K18:K21,FALSE,TRUE)} -> 2.0371578 | N18: 0 | O18: =TINV(0.32,N21)*M19 -> 0.14602393 | P18: =O18*100/M18 -> 7.1680224 | Q18: =-1.99*273*LN(M18)/1000 -> -0.38656682 | R18: =ABS(1.99*273*O18/M18/1000) -> 0.038941715
A19: dibenzosuberone-2 | B19: 0.2 | C19: 0.2 | D19: 0.04 | E19: 1 | F19: =1.04/3 -> 0.34666667 | G19: 0.217 | H19: =0.0512+0.0952 -> 0.1464 | I19: =E19/(E19+G19) -> 0.82169269 | J19: =F19/(F19+H19) -> 0.70308275 | K19: =-LN(I19) -> 0.19638881 | L19: =-LN(J19) -> 0.35228069 | M19: 0.12281976 | N19: #N/A
A20: dibenzosuberone-3 | B20: 0.2 | C20: 0.2 | D20: 0.06 | E20: 1 | F20: =0.7907/3 -> 0.26356667 | G20: 0.2689 | H20: =0.0596+0.1144 -> 0.174 | I20: =E20/(E20+G20) -> 0.78808417 | J20: =F20/(F20+H20) -> 0.60234631 | K20: =-LN(I20) -> 0.23815038 | L20: =-LN(J20) -> 0.50692273 | M20: 0.98921306 | N20: 0.052855666
B21: 0.2 | C21: 0.2 | D21: 0.08 | E21: 1 | F21: =0.6882/3 -> 0.2294 | G21: 0.3096 | H21: =0.0653+0.1209 -> 0.1862 | I21: =E21/(E21+G21) -> 0.76359194 | J21: =F21/(F21+H21) -> 0.55197305 | K21: =-LN(I21) -> 0.26972175 | L21: =-LN(J21) -> 0.59425605 | M21: 275.11411 | N21: 3
M22: 0.76859219 | N22: 0.0083811643
A23: 2-methylcyclohexanone(trans) | M23: =M18*2*0.1209/(0.0653+0.1209) -> 2.6454606 | O23: =O18*2*0.25/(0.24+0.25) -> 0.14900401 | P23: =O18*100/M18 -> 7.1680224 | Q23: =-1.99*273*LN(M23)/1000 -> -0.52851761 | R23: =ABS(1.99*273*O23/M23/1000) -> 0.030599363
A24: 2-methylcyclohexanone(cis) | M24: =M18*2*0.0653/(0.0653+0.1209) -> 1.4288551 | O24: =O18*2*0.24/(0.24+0.25) -> 0.14304385 | P24: =O18*100/M18 -> 7.1680224 | Q24: =-1.99*273*LN(M24)/1000 -> -0.19387865 | R24: =ABS(1.99*273*O24/M24/1000) -> 0.054387204
A25: Benzoylacetonitrile | B25: 0.2 | C25: 0.2 | D25: 0.02 | E25: =(6.4886-2)/4 -> 1.12215 | F25: 1 | G25: 0.0657 | H25: 0.1391 | I25: =E25/(E25+G25) -> 0.94468999 | J25: =F25/(F25+H25) -> 0.87788605 | K25: =-LN(I25) -> 0.056898462 | L25: =-LN(J25) -> 0.13023848 | M25: {=LINEST(L25:L28,K25:K28,FALSE,TRUE)} -> 1.9529748 | N25: 0 | O25: =TINV(0.32,N28)*M26 -> 0.051629322 | P25: =O25*100/M25 -> 2.6436246 | Q25: =-1.99*273*LN(M25)/1000 -> -0.3636398 | R25: =ABS(1.99*273*O25/M25/1000) -> 0.014362019
A26: dibenzosuberone-2 | B26: 0.2 | C26: 0.2 | D26: 0.04 | E26: =(6.589-2)/4 -> 1.14725 | F26: 1 | G26: 0.1526 | H26: 0.2746 | I26: =E26/(E26+G26) -> 0.88260184 | J26: =F26/(F26+H26) -> 0.78455986 | K26: =-LN(I26) -> 0.1248811 | L26: =-LN(J26) -> 0.2426324 | M26: 0.04342508 | N26: #N/A
A27: dibenzosuberone-3 | B27: 0.2 | C27: 0.2 | D27: 0.06 | E27: =(7.0095-2)/4 -> 1.252375 | F27: 1 | G27: 0.2441 | H27: 0.399 | I27: =E27/(E27+G27) -> 0.83688334 | J27: =F27/(F27+H27) -> 0.71479628 | K27: =-LN(I27) -> 0.17807059 | L27: =-LN(J27) -> 0.3357577 | M27: 0.99851896 | N27: 0.013457865
B28: 0.2 | C28: 0.2 | D28: 0.08 | E28: =(7.3278-2)/4 -> 1.33195 | F28: 1 | G28: 0.3167 | H28: 0.5254 | I28: =E28/(E28+G28) -> 0.80790344 | J28: =F28/(F28+H28) -> 0.65556575 | K28: =-LN(I28) -> 0.21331274 | L28: =-LN(J28) -> 0.42225667 | M28: 2022.6093 | N28: 3
M29: 0.36632313 | N29: 0.00054334239
A30: Isopherone Oxide | B30: 0.2 | C30: 0.2 | D30: 0.02 | E30: 1 | F30: 0.8168 | G30: 0.1244 | H30: =0.1856+0.0269 -> 0.2125 | I30: =E30/(E30+G30) -> 0.88936322 | J30: =F30/(F30+H30) -> 0.79354901 | K30: =-LN(I30) -> 0.11724956 | L30: =-LN(J30) -> 0.23123997 | M30: {=LINEST(L30:L32,K30:K32,FALSE,TRUE)} -> 1.9395529 | N30: 0 | O30: =TINV(0.32,N33)*M31 -> 0.0094531866 | P30: =O30*100/M30 -> 0.48738998 | Q30: =-1.99*273*LN(M30)/1000 -> -0.35989329 | R30: =ABS(1.99*273*O30/M30/1000) -> 0.0026478435
A31: dibenzosuberone-2 | B31: 0.2 | C31: 0.2 | D31: 0.04 | E31: 1 | F31: 0.7608 | G31: 0.2427 | H31: =0.3486+0.049 -> 0.3976 | I31: =E31/(E31+G31) -> 0.80469944 | J31: =F31/(F31+H31) -> 0.65676796 | K31: =-LN(I31) -> 0.21728643 | L31: =-LN(J31) -> 0.42042451 | M31: 0.0072074883 | N31: #N/A
A32: dibenzosuberone-3 | B32: 0.2 | C32: 0.2 | D32: 0.06 | E32: 1 | F32: 0.698 | G32: 0.3616 | H32: =0.5015+0.0697 -> 0.5712 | I32: =E32/(E32+G32) -> 0.73443008 | J32: =F32/(F32+H32) -> 0.54995273 | K32: =-LN(I32) -> 0.30866048 | L32: =-LN(J32) -> 0.59792296 | M32: 0.99997238 | N32: 0.0028488471
B33: 0.2 | C33: 0.2 | D33: 0.08 | E33: 1 | M33: 72416.14 | N33: 2
M34: 0.58772432 | N34: 1.623186e-05
A35: Isopherone Oxide(trans) | M35: =M30*2*0.5015/(0.5015+0.0697) -> 3.4057626 | O35: =O30*2*0.25/(0.24+0.25) -> 0.0096461087 | P35: =O30*100/M30 -> 0.48738998 | Q35: =-1.99*273*LN(M35)/1000 -> -0.66576048 | R35: =ABS(1.99*273*O35/M35/1000) -> 0.0015386984
A36: Isopherone Oxide(cis) | M36: =M30*2*0.0697/(0.5015+0.0697) -> 0.47334327 | O36: =O30*2*0.24/(0.24+0.25) -> 0.0092602644 | P36: =O30*100/M30 -> 0.48738998 | Q36: =-1.99*273*LN(M36)/1000 -> 0.40633033 | R36: =ABS(1.99*273*O36/M36/1000) -> 0.010628278
A37: 4,4-dimethylcyclohexanone | B37: 0.2 | C37: 0.2 | D37: 0.04 | E37: 1 | F37: 0.69 | G37: 0.36 | H37: 0.57 | I37: =E37/(E37+G37) -> 0.73529412 | J37: =F37/(F37+H37) -> 0.54761905 | K37: =-LN(I37) -> 0.3074847 | L37: =-LN(J37) -> 0.6021754 | M37: {=LINEST(L37:L39,K37:K39,FALSE,TRUE)} -> 1.9138413 | N37: 0 | O37: =TINV(0.32,N40)*M38 -> 0.051035312 | P37: =O37*100/M37 -> 2.6666429 | Q37: =-1.99*273*LN(M37)/1000 -> -0.35264328 | R37: =ABS(1.99*273*O37/M37/1000) -> 0.014487071
B38: 0.2 | C38: 0.2 | D38: 0.08 | E38: 1 | F38: 0.6 | G38: 0.71 | H38: 0.99 | I38: =E38/(E38+G38) -> 0.58479532 | J38: =F38/(F38+H38) -> 0.37735849 | K38: =-LN(I38) -> 0.53649337 | L38: =-LN(J38) -> 0.97455964 | M38: 0.038911368 | N38: #N/A
B39: 0.2 | C39: 0.2 | D39: 0.12 | E39: 1 | F39: 0.4 | G39: 1.46 | H39: 1.9 | I39: =E39/(E39+G39) -> 0.40650407 | J39: =F39/(F39+H39) -> 0.17391304 | K39: =-LN(I39) -> 0.90016135 | L39: =-LN(J39) -> 1.7491999 | M39: 0.99917394 | N39: 0.042494749
M40: 2419.128 | N40: 2
...

Sheet A1 = benzophenone
B1: Starting amount [mmol] | E1: Endpoint ratio (from 1H-NMR integration) | O1: confidence interval | Q1: ΔΔG [kcal/mol] | S1: note
A2: A2 | B2: A1 | C2: A2 | D2: NaBH4 | E2: A1 | F2: A2 | G2: alcohol1 | H2: alcohol2 | I2: [A1]f / [A1]0 | J2: [A2]f / [A2]0 | K2: -ln([A1]f / [A1]0) | L2: -ln([A2]f / [A2]0) | M2: LINEST analysis | O2: ± 1σ | P2: % | Q2: value | R2: ±68% (1σ)
A3: 2-indanone | B3: 0.2 | C3: 0.2 | D3: 0.04 | E3: 1 | F3: 0.68 | G3: 0 | H3: 0.08 | I3: =E3/(E3+G3) -> 1 | J3: =F3/(F3+H3) -> 0.89473684 | K3: =-LN(I3) -> 0 | L3: =-LN(J3) -> 0.11122564 | M3: {=LINEST(L3:L5,K3:K5,FALSE,TRUE)} -> 101.58148 | N3: 0 | O3: =TINV(0.32,N6)*M4 -> 17.701174 | P3: =O3*100/M3 -> 17.425592 | Q3: =-1.99*273*LN(M3)/1000 -> -2.5103753 | R3: =ABS(1.99*273*O3/M3/1000) -> 0.094668015
B4: 0.2 | C4: 0.2 | D4: 0.08 | E4: 1 | F4: 0.74 | G4: 0.003 | H4: 0.46 | I4: =E4/(E4+G4) -> 0.99700897 | J4: =F4/(F4+H4) -> 0.61666667 | K4: =-LN(I4) -> 0.002995509 | L4: =-LN(J4) -> 0.48342665 | M4: 13.496084 | N4: #N/A
B5: 0.2 | C5: 0.2 | D5: 0.12 | E5: 1 | F5: 0.28 | G5: 0.011 | H5: 0.53 | I5: =E5/(E5+G5) -> 0.98911968 | J5: =F5/(F5+H5) -> 0.34567901 | K5: =-LN(I5) -> 0.01093994 | L5: =-LN(J5) -> 1.0622446 | M5: 0.96590043 | N5: 0.15308116
M6: 56.651768 | N6: 2
M7: 1.3275685 | N7: 0.04686768
A8: 4-tert-buthylcyclohexanone | B8: 0.2 | C8: 0.2 | D8: 0.04 | E8: 1 | F8: 0.686 | G8: 0.004 | H8: 0.341 | I8: =E8/(E8+G8) -> 0.99601594 | J8: =F8/(F8+H8) -> 0.66796495 | K8: =-LN(I8) -> 0.0039920213 | L8: =-LN(J8) -> 0.40351958 | M8: {=LINEST(L8:L10,K8:K10,FALSE,TRUE)} -> 67.530817 | N8: 0 | O8: =TINV(0.32,N11)*M9 -> 2.4844323 | P8: =O8*100/M8 -> 3.6789608 | Q8: =-1.99*273*LN(M8)/1000 -> -2.2885705 | R8: =ABS(1.99*273*O8/M8/1000) -> 0.019986691
B9: 0.2 | C9: 0.2 | D9: 0.08 | E9: 1 | F9: 0.149 | G9: 0.03 | H9: 0.86 | I9: =E9/(E9+G9) -> 0.97087379 | J9: =F9/(F9+H9) -> 0.14767096 | K9: =-LN(I9) -> 0.029558802 | L9: =-LN(J9) -> 1.9127687 | M9: 1.8942308 | N9: #N/A
B10: 0.2 | C10: 0.2 | D10: 0.12 | E10: 1 | F10: 0.029 | G10: 0.054 | H10: 1.02 | I10: =E10/(E10+G10) -> 0.9487666 | J10: =F10/(F10+H10) -> 0.027645377 | K10: =-LN(I10) -> 0.05259245 | L10: =-LN(J10) -> 3.5882968 | M10: 0.99842888 | N10: 0.11452853
M11: 1270.9786 | N11: 2
M12: 16.671152 | N12: 0.02623357
A13: 4-tert-butylcyclohexanone (trans) | M13: =M8*2*0.84/(0.18+0.84) -> 111.22723 | O13: =O8*2*0.84/(0.18+0.84) -> 4.0920061 | P13: =O8*100/M8 -> 3.6789608 | Q13: =-1.99*273*LN(M13)/1000 -> -2.5596575 | R13: =ABS(1.99*273*O13/M13/1000) -> 0.019986691
A14: 4-tert-butylcyclohexanone (cis) | M14: =M8*2*0.18/(0.18+0.84) -> 23.834406 | O14: =O8*2*0.18/(0.18+0.84) -> 0.87685846 | P14: =O8*100/M8 -> 3.6789608 | Q14: =-1.99*273*LN(M14)/1000 -> -1.7227799 | R14: =ABS(1.99*273*O14/M14/1000) -> 0.019986691
A15: 4-methylcyclohexanone | B15: 0.2 | C15: 0.2 | D15: 0.04 | E15: 1 | F15: 0.4 | G15: 0.008 | H15: 0.35 | I15: =E15/(E15+G15) -> 0.99206349 | J15: =F15/(F15+H15) -> 0.53333333 | K15: =-LN(I15) -> 0.0079681696 | L15: =-LN(J15) -> 0.62860866 | M15: {=LINEST(L15:L16,K15:K16,FALSE,TRUE)} -> 64.860689 | N15: 0 | O15: =TINV(0.32,N18)*M16 -> 6.8792047 | P15: =O15*100/M15 -> 10.606123 | Q15: =-1.99*273*LN(M15)/1000 -> -2.2666538 | R15: =ABS(1.99*273*O15/M15/1000) -> 0.057619887
B16: 0.2 | C16: 0.2 | D16: 0.08 | E16: 1 | F16: 0.125 | G16: 0.03 | H16: 0.7 | I16: =E16/(E16+G16) -> 0.97087379 | J16: =F16/(F16+H16) -> 0.15151515 | K16: =-LN(I16) -> 0.029558802 | L16: =-LN(J16) -> 1.8870696 | M16: 3.7818748 | N16: #N/A
M17: 0.99661174 | N17: 0.11577816
M18: 294.13643 | N18: 1
M19: 3.9427761 | N19: 0.013404583
A20: 4-methylcyclohexanone (trans) | M20: =M15*2*0.57/(0.13+0.57) -> 105.63026 | O20: =O15*2*0.57/(0.13+0.57) -> 11.203276 | P20: =O15*100/M15 -> 10.606123 | Q20: =-1.99*273*LN(M20)/1000 -> -2.5316083 | R20: =ABS(1.99*273*O20/M20/1000) -> 0.057619887
A21: 4-methylcyclohexanone (cis) | M21: =M15*2*0.13/(0.13+0.57) -> 24.091113 | O21: =O15*2*0.13/(0.13+0.57) -> 2.5551332 | P21: =O15*100/M15 -> 10.606123 | Q21: =-1.99*273*LN(M21)/1000 -> -1.7285999 | R21: =ABS(1.99*273*O21/M21/1000) -> 0.057619887
A22: 4,4-dimethylcyclohexanone | B22: 0.2 | C22: 0.2 | D22: 0.04 | E22: 1 | F22: 0.225 | G22: 0.021 | H22: 0.72 | I22: =E22/(E22+G22) -> 0.97943193 | J22: =F22/(F22+H22) -> 0.23809524 | K22: =-LN(I22) -> 0.020782539 | L22: =-LN(J22) -> 1.4350845 | M22: {=LINEST(L22:L23,K22:K23,FALSE,TRUE)} -> 61.856388 | N22: 0 | O22: =TINV(0.32,N25)*M23 -> 8.3787218 | P22: =O22*100/M22 -> 13.545443 | Q22: =-1.99*273*LN(M22)/1000 -> -2.2408885 | R22: =ABS(1.99*273*O22/M22/1000) -> 0.073588328
B23: 0.2 | C23: 0.2 | D23: 0.08 | E23: 1 | F23: 0.1525 | G23: 0.033 | H23: 0.88 | I23: =E23/(E23+G23) -> 0.96805421 | J23: =F23/(F23+H23) -> 0.14769976 | K23: =-LN(I23) -> 0.03246719 | L23: =-LN(J23) -> 1.9125737 | M23: 4.6062413 | N23: #N/A
M24: 0.99448529 | N24: 0.17756641
M25: 180.33322 | N25: 1
M26: 5.685876 | N26: 0.031529831
A27: 3-methylcyclohexanone | B27: 0.2 | C27: 0.2 | D27: 0.04 | E27: 1 | F27: 0.42 | G27: 0.016 | H27: 0.44 | I27: =E27/(E27+G27) -> 0.98425197 | J27: =F27/(F27+H27) -> 0.48837209 | K27: =-LN(I27) -> 0.015873349 | L27: =-LN(J27) -> 0.71667768 | M27: {=LINEST(L27:L28,K27:K28,FALSE,TRUE)} -> 54.491838 | N27: 0 | O27: =TINV(0.32,N30)*M28 -> 6.877464 | P27: =O27*100/M27 -> 12.62109 | Q27: =-1.99*273*LN(M27)/1000 -> -2.1720211 | R27: =ABS(1.99*273*O27/M27/1000) -> 0.068566596
B28: 0.2 | C28: 0.2 | D28: 0.08 | E28: 1 | F28: 0.08 | G28: 0.04 | H28: 0.64 | I28: =E28/(E28+G28) -> 0.96153846 | J28: =F28/(F28+H28) -> 0.11111111 | K28: =-LN(I28) -> 0.039220713 | L28: =-LN(J28) -> 2.1972246 | M28: 3.7809178 | N28: #N/A
M29: 0.99520878 | N29: 0.15997472
M30: 207.71528 | N30: 1
M31: 5.3158308 | N31: 0.025591911
A32: cis-3-methylcyclohexanone | M32: =M27*2*0.49/(0.49+0.15) -> 83.440627 | O32: =O27*0.49/(0.49+0.15) -> 5.2655584 | P32: =O27*100/M27 -> 12.62109 | Q32: =-1.99*273*LN(M32)/1000 -> -2.4035 | R32: =ABS(1.99*273*O32/M32/1000) -> 0.034283298
A33: trans-3-methylcyclohexanone | M33: =M27*2*0.15/(0.49+0.15) -> 25.543049 | O33: =O27*0.15/(0.49+0.15) -> 1.6119056 | P33: =O27*100/M27 -> 12.62109 | Q33: =-1.99*273*LN(M33)/1000 -> -1.7603932 | R33: =ABS(1.99*273*O33/M33/1000) -> 0.034283298
A34: 1-chloropinacolin | B34: 0.2 | C34: 0.2 | D34: 0.04 | E34: 1 | F34: 0.375 | G34: 0 | H34: 0.58 | I34: =E34/(E34+G34) -> 1 | J34: =F34/(F34+H34) -> 0.39267016 | K34: =-LN(I34) -> 0 | L34: =-LN(J34) -> 0.93478531 | M34: {=LINEST(L34:L36,K34:K36,FALSE,TRUE)} -> 48.795009 | N34: 0 | O34: =TINV(0.32,N37)*M35 -> 11.589185 | P34: =O34*100/M34 -> 23.750759 | Q34: =-1.99*273*LN(M34)/1000 -> -2.1120317 | R34: =ABS(1.99*273*O34/M34/1000) -> 0.12903075
B35: 0.2 | C35: 0.2 | D35: 0.08 | E35: 1 | F35: 0.135 | G35: 0.009 | H35: 0.78 | I35: =E35/(E35+G35) -> 0.99108028 | J35: =F35/(F35+H35) -> 0.14754098 | K35: =-LN(I35) -> 0.0089597414 | L35: =-LN(J35) -> 1.9136493 | M35: 8.836059 | N35: #N/A
B36: 0.2 | C36: 0.2 | D36: 0.12 | E36: 1 | F36: 0.00125 | G36: 0.15 | H36: 1.04 | I36: =E36/(E36+G36) -> 0.86956522 | J36: =F36/(F36+H36) -> 0.0012004802 | K36: =-LN(I36) -> 0.13976194 | L36: =-LN(J36) -> 6.7250336 | M36: 0.93845273 | N36: 1.2374798
M37: 30.495347 | N37: 2
M38: 46.699242 | N38: 3.0627126
A39: cyclohexanone | B39: 0.2 | C39: 0.2 | D39: 0.04 | E39: 1 | F39: 0.693 | G39: 0.008 | H39: 0.33 | I39: =E39/(E39+G39) -> 0.99206349 | J39: =F39/(F39+H39) -> 0.67741935 | K39: =-LN(I39) -> 0.0079681696 | L39: =-LN(J39) -> 0.38946477 | M39: {=LINEST(L39:L41,K39:K41,FALSE,TRUE)} -> 46.30306 | N39: 0 | O39: =TINV(0.32,N42)*M40 -> 4.9980796 | P39: =O39*100/M39 -> 10.794275 | Q39: =-1.99*273*LN(M39)/1000 -> -2.0835535 | R39: =ABS(1.99*273*O39/M39/1000) -> 0.058642057
B40: 0.2 | C40: 0.2 | D40: 0.08 | E40: 1 | F40: 0.395 | G40: 0.015 | H40: 0.5 | I40: =E40/(E40+G40) -> 0.98522167 | J40: =F40/(F40+H40) -> 0.44134078 | K40: =-LN(I40) -> 0.014888612 | L40: =-LN(J40) -> 0.81793795 | M40: 3.8107362 | N40: #N/A
...

Sheet A1=dibenzosuberone
B1: Starting amount [mmol] | E1: Endpoint ratio (from 1H-NMR integration) | O1: confidence interval | Q1: ΔΔG [kcal/mol] | S1: note
A2: A2 | B2: A1 | C2: A2 | D2: NaBH4 | E2: A1 | F2: A2 | G2: alcohol1 | H2: alcohol2 | I2: [A1]f / [A1]0 | J2: [A2]f / [A2]0 | K2: -ln([A1]f / [A1]0) | L2: -ln([A2]f / [A2]0) | M2: LINEST analysis | O2: ± 1σ | P2: % | Q2: value | R2: ±68% (1σ)
A3: 2-nonanone | B3: 0.2 | C3: 0.2 | D3: 0.04 | E3: 1 | F3: 0.65 | G3: 0.008 | H3: 0.4 | I3: =E3/(E3+G3) -> 0.99206349 | J3: =F3/(F3+H3) -> 0.61904762 | K3: =-LN(I3) -> 0.0079681696 | L3: =-LN(J3) -> 0.47957308 | M3: {=LINEST(L3:L5,K3:K5,FALSE,TRUE)} -> 52.405369 | N3: 0 | O3: =TINV(0.32,N6)*M4 -> 4.4938312 | P3: =O3*100/M3 -> 8.575135 | Q3: =-1.99*273*LN(M3)/1000 -> -2.1508108 | R3: =ABS(1.99*273*O3/M3/1000) -> 0.046586136
A4: 2-nonanone-2 | B4: 0.2 | C4: 0.2 | D4: 0.08 | E4: 1 | F4: 0.44 | G4: 0.014 | H4: 0.57 | I4: =E4/(E4+G4) -> 0.98619329 | J4: =F4/(F4+H4) -> 0.43564356 | K4: =-LN(I4) -> 0.013902905 | L4: =-LN(J4) -> 0.83093088 | M4: 3.426277 | N4: #N/A
A5: 2-nonanone-3 | B5: 0.2 | C5: 0.2 | D5: 0.12 | E5: 1 | F5: 0.32 | G5: 0.025 | H5: 0.76 | I5: =E5/(E5+G5) -> 0.97560976 | J5: =F5/(F5+H5) -> 0.2962963 | K5: =-LN(I5) -> 0.024692613 | L5: =-LN(J5) -> 1.2163953 | M5: 0.99152331 | N5: 0.10085761
M6: 233.94115 | N6: 2
M7: 2.3797095 | N7: 0.020344514
A8: 5-nonanone | B8: 0.2 | C8: 0.2 | D8: 0.04 | E8: 1 | F8: 0.673 | G8: 0.018 | H8: 0.24 | I8: =E8/(E8+G8) -> 0.98231827 | J8: =F8/(F8+H8) -> 0.73713034 | K8: =-LN(I8) -> 0.017839918 | L8: =-LN(J8) -> 0.30499055 | M8: {=LINEST(L8:L10,K8:K10,FALSE,TRUE)} -> 13.183098 | N8: 0 | O8: =TINV(0.32,N11)*M9 -> 1.5483456 | P8: =O8*100/M8 -> 11.74493 | Q8: =-1.99*273*LN(M8)/1000 -> -1.4010583 | R8: =ABS(1.99*273*O8/M8/1000) -> 0.06380668
A9: 5-nonanone-2 | B9: 0.2 | C9: 0.2 | D9: 0.08 | E9: 1 | F9: 0.495 | G9: 0.039 | H9: 0.42 | I9: =E9/(E9+G9) -> 0.96246391 | J9: =F9/(F9+H9) -> 0.54098361 | K9: =-LN(I9) -> 0.038258712 | L9: =-LN(J9) -> 0.6143663 | M9: 1.1805208 | N9: #N/A
A10: 5-nonanone-3 | B10: 0.2 | C10: 0.2 | D10: 0.12 | E10: 1 | F10: 0.368 | G10: 0.081 | H10: 0.59 | I10: =E10/(E10+G10) -> 0.92506938 | J10: =F10/(F10+H10) -> 0.38413361 | K10: =-LN(I10) -> 0.077886539 | L10: =-LN(J10) -> 0.95676484 | M10: 0.98421544 | N10: 0.10458311
M11: 124.7061 | N11: 2
M12: 1.3639889 | N12: 0.021875255
A13: 2,6-dimethyl-4-heptanone | B13: 0.2 | C13: 0.2 | D13: 0.04 | E13: 1 | F13: 0.75 | G13: 0.14 | H13: 0.05 | I13: =E13/(E13+G13) -> 0.87719298 | J13: =F13/(F13+H13) -> 0.9375 | K13: =-LN(I13) -> 0.13102826 | L13: =-LN(J13) -> 0.064538521 | M13: {=LINEST(L13:L15,K13:K15,FALSE,TRUE)} -> 0.5676269 | N13: 0 | O13: =TINV(0.32,N16)*M14 -> 0.043115905 | P13: =O13*100/M13 -> 7.5958176 | Q13: =-1.99*273*LN(M13)/1000 -> 0.30764888 | R13: =ABS(1.99*273*O13/M13/1000) -> 0.041265798
A14: 2,6-dimethyl-4-heptanone-2 | B14: 0.2 | C14: 0.2 | D14: 0.08 | E14: 1 | F14: 0.79 | G14: 0.23 | H14: 0.09 | I14: =E14/(E14+G14) -> 0.81300813 | J14: =F14/(F14+H14) -> 0.89772727 | K14: =-LN(I14) -> 0.20701417 | L14: =-LN(J14) -> 0.10788896 | M14: 0.032873294 | N14: #N/A
A15: 2,6-dimethyl-4-heptanone-3 | B15: 0.2 | C15: 0.2 | D15: 0.12 | E15: 1 | F15: 0.67 | G15: 0.34 | H15: 0.13 | I15: =E15/(E15+G15) -> 0.74626866 | J15: =F15/(F15+H15) -> 0.8375 | K15: =-LN(I15) -> 0.29266961 | L15: =-LN(J15) -> 0.17733402 | M15: 0.99333674 | N15: 0.012547042
M16: 298.15322 | N16: 2
M17: 0.046937745 | N17: 0.00031485654
A18: 10,10-Dimethylanthracen-9(10H)-one | B18: 0.2 | C18: 0.2 | D18: 0.04 | E18: 1 | F18: 1.229 | G18: 0.246 | H18: 0.033 | I18: =E18/(E18+G18) -> 0.80256822 | J18: =F18/(F18+H18) -> 0.97385103 | K18: =-LN(I18) -> 0.21993842 | L18: =-LN(J18) -> 0.026496934 | M18: {=LINEST(L18:L20,K18:K20,FALSE,TRUE)} -> 0.11891936 | N18: 0 | O18: =TINV(0.32,N21)*M19 -> 0.0019617211 | P18: =O18*100/M18 -> 1.6496229 | Q18: =-1.99*273*LN(M18)/1000 -> 1.15679 | R18: =ABS(1.99*273*O18/M18/1000) -> 0.0089619063
A19: 10,10-Dimethylanthracen-9(10H)-one-2 | B19: 0.2 | C19: 0.2 | D19: 0.08 | E19: 1 | F19: 1.512 | G19: 0.603 | H19: 0.083 | I19: =E19/(E19+G19) -> 0.62383032 | J19: =F19/(F19+H19) -> 0.94796238 | K19: =-LN(I19) -> 0.47187687 | L19: =-LN(J19) -> 0.053440458 | M19: 0.0014956948 | N19: #N/A
A20: 10,10-Dimethylanthracen-9(10H)-one-3 | B20: 0.2 | C20: 0.2 | D20: 0.12 | E20: 1 | F20: 2.962 | G20: 2.482 | H20: 0.477 | I20: =E20/(E20+G20) -> 0.28719127 | J20: =F20/(F20+H20) -> 0.86129689 | K20: =-LN(I20) -> 1.2476068 | L20: =-LN(J20) -> 0.14931602 | M20: 0.99968372 | N20: 0.002021991
M21: 6321.4865 | N21: 2
M22: 0.025845066 | N22: 8.1768951e-06
A23: (+)-camphor | B23: 0.2 | C23: 0.2 | D23: 0.08 | E23: 1 | F23: 2.18 | G23: 1.54 | H23: 0.144 | I23: =E23/(E23+G23) -> 0.39370079 | J23: =F23/(F23+H23) -> 0.93803787 | K23: =-LN(I23) -> 0.93216408 | L23: =-LN(J23) -> 0.063964962 | M23: {=LINEST(L23:L25,K23:K25,FALSE,TRUE)} -> 0.070570076 | N23: 0 | O23: =TINV(0.32,N26)*M24 -> 0.0015299737 | P23: =O23*100/M23 -> 2.1680205 | Q23: =-1.99*273*LN(M23)/1000 -> 1.4402898 | R23: =ABS(1.99*273*O23/M23/1000) -> 0.011778205
A24: (+)-camphor-2 | B24: 0.2 | C24: 0.2 | D24: 0.12 | E24: 1 | F24: 2.81 | G24: 2.5 | H24: 0.268 | I24: =E24/(E24+G24) -> 0.28571429 | J24: =F24/(F24+H24) -> 0.91293047 | K24: =-LN(I24) -> 1.252763 | L24: =-LN(J24) -> 0.091095552 | M24: 0.0011665133 | N24: #N/A
A25: (+)-camphor-3 | B25: 0.2 | C25: 0.2 | D25: 0.16 | E25: 1 | F25: 3.3 | G25: 3.05 | H25: 0.338 | I25: =E25/(E25+G25) -> 0.24691358 | J25: =F25/(F25+H25) -> 0.90709181 | K25: =-LN(I25) -> 1.3987169 | L25: =-LN(J25) -> 0.097511612 | M25: 0.99945383 | N25: 0.0024454398
M26: 3659.8373 | N26: 2
M27: 0.02188647 | N27: 1.1960351e-05
A28: camphor (exo) | M28: =M23*2*0.29/(0.048+0.29) -> 0.12109658 | O28: =O23*2*0.29/(0.048+0.29) -> 0.0026253987 | P28: =O23*100/M23 -> 2.1680205 | Q28: =-1.99*273*LN(M28)/1000 -> 1.1469336 | R28: =ABS(1.99*273*O28/M28/1000) -> 0.011778205
A29: camphor (endo) | M29: =M23*2*0.048/(0.048+0.29) -> 0.020043572 | O29: =O23*2*0.048/(0.048+0.29) -> 0.00043454875 | P29: =O23*100/M23 -> 2.1680205 | Q29: =-1.99*273*LN(M29)/1000 -> 2.1241025 | R29: =ABS(1.99*273*O29/M29/1000) -> 0.011778205
A30: (-)-fenchone | B30: 0.2 | C30: 0.2 | D30: 0.08 | E30: 1 | F30: 1.59 | G30: 0.87 | H30: 0.048 | I30: =E30/(E30+G30) -> 0.53475936 | J30: =F30/(F30+H30) -> 0.97069597 | K30: =-LN(I30) -> 0.62593843 | L30: =-LN(J30) -> 0.029741969 | M30: {=LINEST(L30:L32,K30:K32,FALSE,TRUE)} -> 0.067070359 | N30: 0 | O30: =TINV(0.32,N33)*M31 -> 0.007769497 | P30: =O30*100/M30 -> 11.584099 | Q30: =-1.99*273*LN(M30)/1000 -> 1.4679226 | R30: =ABS(1.99*273*O30/M30/1000) -> 0.062932936
A31: (-)-fenchone-2 | B31: 0.2 | C31: 0.2 | D31: 0.12 | E31: 1 | F31: 1.59 | G31: 1.04 | H31: 0.081 | I31: =E31/(E31+G31) -> 0.49019608 | J31: =F31/(F31+H31) -> 0.95152603 | K31: =-LN(I31) -> 0.71294981 | L31: =-LN(J31) -> 0.049688233 | M31: 0.0059237759 | N31: #N/A
A32: (-)-fenchone-3 | B32: 0.2 | C32: 0.2 | D32: 0.16 | E32: 1 | F32: 2.95 | G32: 2.59 | H32: 0.28 | I32: =E32/(E32+G32) -> 0.27855153 | J32: =F32/(F32+H32) -> 0.91331269 | K32: =-LN(I32) -> 1.2781522 | L32: =-LN(J32) -> 0.090676967 | M32: 0.98463818 | N32: 0.0094293589
M33: 128.19291 | N33: 2
M34: 0.011397992 | N34: 0.00017782562
A35: fenchone (endo) | M35: =M30*2*0.93/(0.93+0.053) -> 0.12690831 | O35: =O30*2*0.93/(0.93+0.053) -> 0.014701184 | P35: =O30*100/M30 -> 11.584099 | Q35: =-1.99*273*LN(M35)/1000 -> 1.1214671 | R35: =ABS(1.99*273*O35/M35/1000) -> 0.062932936 | S35: Calculated diastereoselectivity from the reduction results of the pure product
A36: fenchone (exo) | M36: =M30*2*0.053/(0.93+0.053) -> 0.007232409 | O36: =O30*2*0.053/(0.93+0.053) -> 0.00083780944 | P36: =O30*100/M30 -> 11.584099 | Q36: =-1.99*273*LN(M36)/1000 -> 2.6778773 | R36: =ABS(1.99*273*O36/M36/1000) -> 0.062932936 | S36: Calculated diastereoselectivity from the reduction results of the pure product

Sheet others
B1: Starting amount [mmol] in 1mL MeOH | E1: Endpoint ratio (from 1H-NMR integration) | O1: confidence interval | Q1: ΔΔG [kcal/mol] | S1: note
B2: A1 | C2: A2 | D2: NaBH4 | E2: A1 | F2: A2 | G2: alcohol1 | H2: alcohol2 | I2: [A1]f / [A1]0 | J2: [A2]f / [A2]0 | K2: -ln([A1]f / [A1]0) | L2: -ln([A2]f / [A2]0) | M2: LINEST analysis | O2: ± 1σ | P2: % | Q2: value | R2: ±68% (1σ)
A3: A1 = 5-nonanone, A2 = adamantanone | B3: 0.2 | C3: 0.2 | D3: 0.02 | E3: 1.92 | F3: 1 | G3: 0.11 | H3: 0.98 | I3: =E3/(E3+G3) -> 0.94581281 | J3: =F3/(F3+H3) -> 0.50505051 | K3: =-LN(I3) -> 0.055710607 | L3: =-LN(J3) -> 0.68309684 | M3: {=LINEST(L3:L5,K3:K5,FALSE,TRUE)} -> 13.055276 | N3: 0 | O3: =_xlfn.T.INV.2T(0.32,N6)*M4 -> 0.20349358 | P3: =O3*100/M3 -> 1.5587076 | Q3: =-1.99*273*LN(M3)/1000 -> -1.3957651 | R3: =ABS(1.99*273*O3/M3/1000) -> 0.0084679908
B4: 0.2 | C4: 0.2 | D4: 0.04 | E4: 2.92 | F4: 1 | G4: 0.26 | H4: 2.08 | I4: =E4/(E4+G4) -> 0.91823899 | J4: =F4/(F4+H4) -> 0.32467532 | K4: =-LN(I4) -> 0.085297581 | L4: =-LN(J4) -> 1.1249296 | M4: 0.15515166 | N4: #N/A
B5: 0.2 | C5: 0.2 | D5: 0.06 | E5: 10.13 | F5: 1 | G5: 2.06 | H5: 10.3 | I5: =E5/(E5+G5) -> 0.83100902 | J5: =F5/(F5+H5) -> 0.088495575 | K5: =-LN(I5) -> 0.18511463 | L5: =-LN(J5) -> 2.4248027 | M5: 0.99971761 | N5: 0.03278321
M6: 7080.4238 | N6: 2
M7: 7.6096067 | N7: 0.0021494777
A8: A1 = adamantanone, A2 = 1-cyclopentylethanone | B8: 0.2 | C8: 0.2 | D8: 0.02 | E8: 1 | F8: 1.292 | G8: 0.638 | H8: 0.148 | I8: =E8/(E8+G8) -> 0.61050061 | J8: =F8/(F8+H8) -> 0.89722222 | K8: =-LN(I8) -> 0.49347599 | L8: =-LN(J8) -> 0.10845171 | M8: {=LINEST(L8:L10,K8:K10,FALSE,TRUE)} -> 0.22594973 | N8: 0 | O8: =_xlfn.T.INV.2T(0.32,N11)*M9 -> 0.0030327068 | P8: =O8*100/M8 -> 1.3422042 | Q8: =-1.99*273*LN(M8)/1000 -> 0.80808301 | R8: =ABS(1.99*273*O8/M8/1000) -> 0.0072917928
B9: 0.2 | C9: 0.2 | D9: 0.04 | E9: 1 | F9: 1.411 | G9: 0.69 | H9: 0.175 | I9: =E9/(E9+G9) -> 0.59171598 | J9: =F9/(F9+H9) -> 0.88965952 | K9: =-LN(I9) -> 0.52472853 | L9: =-LN(J9) -> 0.11691645 | M9: 0.0023122572 | N9: #N/A
B10: 0.2 | C10: 0.2 | D10: 0.06 | E10: 1 | F10: 1.937 | G10: 1.836 | H10: 0.52 | I10: =E10/(E10+G10) -> 0.35260931 | J10: =F10/(F10+H10) -> 0.78835979 | K10: =-LN(I10) -> 1.0423946 | L10: =-LN(J10) -> 0.23780071 | M10: 0.99979059 | N10: 0.0029297723
M11: 9548.8565 | N11: 2
M12: 0.08196324 | N12: 1.7167132e-05
A13: A1 = 1-cycloentylethanone, A2 = 5-nonanone | B13: 0.2 | C13: 0.2 | D13: 0.02 | E13: 1 | F13: 1.419 | G13: 0.373 | H13: 0.148 | I13: =E13/(E13+G13) -> 0.72833212 | J13: =F13/(F13+H13) -> 0.90555201 | K13: =-LN(I13) -> 0.31699813 | L13: =-LN(J13) -> 0.099210565 | M13: {=LINEST(L13:L15,K13:K15,FALSE,TRUE)} -> 0.3107138 | N13: 0 | O13: =_xlfn.T.INV.2T(0.32,N16)*M14 -> 0.0099686561 | P13: =O13*100/M13 -> 3.2083081 | Q13: =-1.99*273*LN(M13)/1000 -> 0.63501909 | R13: =ABS(1.99*273*O13/M13/1000) -> 0.017429776
B14: 0.2 | C14: 0.2 | D14: 0.04 | E14: 1 | F14: 1.678 | G14: 0.674 | H14: 0.276 | I14: =E14/(E14+G14) -> 0.59737157 | J14: =F14/(F14+H14) -> 0.85875128 | K14: =-LN(I14) -> 0.51521597 | L14: =-LN(J14) -> 0.15227595 | M14: 0.0076005029 | N14: #N/A
B15: 0.2 | C15: 0.2 | D15: 0.06 | E15: 1 | F15: 1.797 | G15: 0.95 | H15: 0.427 | I15: =E15/(E15+G15) -> 0.51282051 | J15: =F15/(F15+H15) -> 0.8080036 | K15: =-LN(I15) -> 0.66782937 | L15: =-LN(J15) -> 0.21318877 | M15: 0.99880471 | N15: 0.0068486031
M16: 1671.2308 | N16: 2
M17: 0.078386344 | N17: 9.3806728e-05
A18: A1 = adamantanone, A2 = 4,4-dimethoxy | B18: 0.2 | C18: 0.2 | D18: 0.02 | E18: 1 | F18: 1.218 | G18: 0.522 | H18: 0.12 | I18: =E18/(E18+G18) -> 0.65703022 | J18: =F18/(F18+H18) -> 0.9103139 | K18: =-LN(I18) -> 0.42002526 | L18: =-LN(J18) -> 0.093965792 | M18: {=LINEST(L18:L20,K18:K20,FALSE,TRUE)} -> 0.22277369 | N18: 0 | O18: =_xlfn.T.INV.2T(0.32,N21)*M19 -> 0.0037549201 | P18: =O18*100/M18 -> 1.6855312 | Q18: =-1.99*273*LN(M18)/1000 -> 0.81577362 | R18: =ABS(1.99*273*O18/M18/1000) -> 0.0091569856
B19: 0.2 | C19: 0.2 | D19: 0.04 | E19: 1 | F19: 1.575 | G19: 1.107 | H19: 0.296 | I19: =E19/(E19+G19) -> 0.47460845 | J19: =F19/(F19+H19) -> 0.84179583 | K19: =-LN(I19) -> 0.74526513 | L19: =-LN(J19) -> 0.17221778 | M19: 0.0028629016 | N19: #N/A
B20: 0.2 | C20: 0.2 | D20: 0.06 | E20: 1 | F20: 2.735 | G20: 3.466 | H20: 1.07 | I20: =E20/(E20+G20) -> 0.22391402 | J20: =F20/(F20+H20) -> 0.71879106 | K20: =-LN(I20) -> 1.4964932 | L20: =-LN(J20) -> 0.33018456 | M20: 0.9996698 | N20: 0.0049349425
M21: 6055.0112 | N21: 2
M22: 0.14746167 | N22: 4.8707314e-05
A23: A1 = 4,4-dimethoxy, A2 = 5-nonanone | B23: 0.2 | C23: 0.2 | D23: 0.02 | E23: 1 | F23: 0.625 | G23: 0.1 | H23: 0.196 | I23: =E23/(E23+G23) -> 0.90909091 | J23: =F23/(F23+H23) -> 0.76126675 | K23: =-LN(I23) -> 0.09531018 | L23: =-LN(J23) -> 0.27277146 | M23: {=LINEST(L23:L25,K23:K25,FALSE,TRUE)} -> 2.977704 | N23: 0 | O23: =_xlfn.T.INV.2T(0.32,N26)*M24 -> 0.066829077 | P23: =O23*100/M23 -> 2.2443156 | Q23: =-1.99*273*LN(M23)/1000 -> -0.59279044 | R23: =ABS(1.99*273*O23/M23/1000) -> 0.012192694
B24: 0.2 | C24: 0.2 | D24: 0.04 | E24: 1 | F24: 0.525 | G24: 0.17 | H24: 0.327 | I24: =E24/(E24+G24) -> 0.85470085 | J24: =F24/(F24+H24) -> 0.61619718 | K24: =-LN(I24) -> 0.15700375 | L24: =-LN(J24) -> 0.48418826 | M24: 0.050953167 | N24: #N/A
B25: 0.2 | C25: 0.2 | D25: 0.06 | E25: 1 | F25: 0.427 | G25: 0.257 | H25: 0.411 | I25: =E25/(E25+G25) -> 0.79554495 | J25: =F25/(F25+H25) -> 0.50954654 | K25: =-LN(I25) -> 0.22872793 | L25: =-LN(J25) -> 0.67423409 | M25: 0.99941473 | N25: 0.014946803
M26: 3415.2358 | N26: 2
M27: 0.76298734 | N27: 0.00044681386

Sheet diketone_reduction_results
B1: starting material [mmol] | E1: Endpoint ratio (from 1H-NMR integration) | J1: Endpoint ratio (scaled)
A2: entry | B2: diketone | C2: NaBH4 | D2: reaction time [min] | E2: 3one | F2: α-3ol | G2: β-3ol | H2: α-20ol | I2: β-20ol | J2: reaction rate [%] | K2: 3one | L2: 1 | M2: 2 | N2: 20one | O2: 3 | P2: 4 | Q2: note
A3: 0 | B3: - | C3: - | D3: - | E3: - | F3: - | G3: - | H3: - | I3: - | J3: 0 | K3: 100 | L3: 0 | M3: 0 | N3: 100 | O3: 0 | P3: 0
A4: 1 | B4: 0.5 | C4: 0.04 | D4: 60 | E4: 1 | F4: 0.042 | G4: 0.27 | H4: 0 | I4: 0 | J4: =100-SUM(K4,N4)/2 -> 11.890244 | K4: =E4/SUM($E4:$G4)*100 -> 76.219512 | L4: =F4/SUM($E4:$G4)*100 -> 3.2012195 | M4: =G4/SUM($E4:$G4)*100 -> 20.579268 | N4: =100-(SUM(H4:I4)/SUM($E4:$G4)*100) -> 100 | O4: =H4/SUM($E4:$G4)*100 -> 0 | P4: =I4/SUM($E4:$G4)*100 -> 0
A5: 2 | B5: 0.5 | C5: 0.07 | D5: 60 | E5: 1 | F5: 0.13 | G5: 0.66 | H5: 0 | I5: 0 | J5: =100-SUM(K5,N5)/2 -> 22.067039 | K5: =E5/SUM($E5:$G5)*100 -> 55.865922 | L5: =F5/SUM($E5:$G5)*100 -> 7.2625698 | M5: =G5/SUM($E5:$G5)*100 -> 36.871508 | N5: =100-(SUM(H5:I5)/SUM($E5:$G5)*100) -> 100 | O5: =H5/SUM($E5:$G5)*100 -> 0 | P5: =I5/SUM($E5:$G5)*100 -> 0
A6: 3 | B6: 0.5 | C6: 0.1 | D6: 60 | E6: 1 | F6: 0.17 | G6: 1 | H6: 0 | I6: 0 | J6: =100-SUM(K6,N6)/2 -> 26.958525 | K6: =E6/SUM($E6:$G6)*100 -> 46.082949 | L6: =F6/SUM($E6:$G6)*100 -> 7.8341014 | M6: =G6/SUM($E6:$G6)*100 -> 46.082949 | N6: =100-(SUM(H6:I6)/SUM($E6:$G6)*100) -> 100 | O6: =H6/SUM($E6:$G6)*100 -> 0 | P6: =I6/SUM($E6:$G6)*100 -> 0
A7: 4 | B7: 0.1 | C7: 0.025 | D7: 60 | E7: 1 | F7: 0.24 | G7: 1.65 | H7: 0 | I7: 0 | J7: =100-SUM(K7,N7)/2 -> 32.698962 | K7: =E7/SUM($E7:$G7)*100 -> 34.602076 | L7: =F7/SUM($E7:$G7)*100 -> 8.3044983 | M7: =G7/SUM($E7:$G7)*100 -> 57.093426 | N7: =100-(SUM(H7:I7)/SUM($E7:$G7)*100) -> 100 | O7: =H7/SUM($E7:$G7)*100 -> 0 | P7: =I7/SUM($E7:$G7)*100 -> 0
A8: 5 | B8: 0.1 | C8: 0.05 | D8: 60 | E8: 1 | F8: 0.33 | G8: 2.21 | H8: 0 | I8: 0 | J8: =100-SUM(K8,N8)/2 -> 35.875706 | K8: =E8/SUM($E8:$G8)*100 -> 28.248588 | L8: =F8/SUM($E8:$G8)*100 -> 9.3220339 | M8: =G8/SUM($E8:$G8)*100 -> 62.429379 | N8: =100-(SUM(H8:I8)/SUM($E8:$G8)*100) -> 100 | O8: =H8/SUM($E8:$G8)*100 -> 0 | P8: =I8/SUM($E8:$G8)*100 -> 0
A9: 6 | B9: 0.1 | C9: 0.03 | D9: 60 | E9: 1 | F9: 0.42 | G9: 2.45 | H9: 0 | I9: 0 | J9: =100-SUM(K9,N9)/2 -> 37.080103 | K9: =E9/SUM($E9:$G9)*100 -> 25.839793 | L9: =F9/SUM($E9:$G9)*100 -> 10.852713 | M9: =G9/SUM($E9:$G9)*100 -> 63.307494 | N9: =100-(SUM(H9:I9)/SUM($E9:$G9)*100) -> 100 | O9: =H9/SUM($E9:$G9)*100 -> 0 | P9: =I9/SUM($E9:$G9)*100 -> 0
A10: 7 | B10: 0.1 | C10: 0.04 | D10: 60 | E10: 1 | F10: 0.56 | G10: 3.56 | H10: 0 | I10: 0 | J10: =100-SUM(K10,N10)/2 -> 40.234375 | K10: =E10/SUM($E10:$G10)*100 -> 19.53125 | L10: =F10/SUM($E10:$G10)*100 -> 10.9375 | M10: =G10/SUM($E10:$G10)*100 -> 69.53125 | N10: =100-(SUM(H10:I10)/SUM($E10:$G10)*100) -> 100 | O10: =H10/SUM($E10:$G10)*100 -> 0 | P10: =I10/SUM($E10:$G10)*100 -> 0
A11: 8 | B11: 0.08 | C11: 0.04 | D11: 5 | E11: 0.33 | F11: 1 | G11: 7.17 | H11: =I11/9 -> 0.022222222 | I11: 0.2 | J11: =100-SUM(K11,N11)/2 -> 49.366013 | K11: =E11/SUM($E11:$G11)*100 -> 3.8823529 | L11: =F11/SUM($E11:$G11)*100 -> 11.764706 | M11: =G11/SUM($E11:$G11)*100 -> 84.352941 | N11: =100-(SUM(H11:I11)/SUM($E11:$G11)*100) -> 97.385621 | O11: =H11/SUM($E11:$G11)*100 -> 0.26143791 | P11: =I11/SUM($E11:$G11)*100 -> 2.3529412
A12: 9 | B12: 0.08 | C12: 0.04 | D12: 10 | E12: 0.23 | F12: 1 | G12: 7.18 | H12: =I12/9 -> 0.027 | I12: 0.243 | J12: =100-SUM(K12,N12)/2 -> 50.237812 | K12: =E12/SUM($E12:$G12)*100 -> 2.7348395 | L12: =F12/SUM($E12:$G12)*100 -> 11.890606 | M12: =G12/SUM($E12:$G12)*100 -> 85.374554 | N12: =100-(SUM(H12:I12)/SUM($E12:$G12)*100) -> 96.789536 | O12: =H12/SUM($E12:$G12)*100 -> 0.32104637 | P12: =I12/SUM($E12:$G12)*100 -> 2.8894174
